Workbook

Sheet 表紙
B1: 別記様式第１号の７（第33条の18関係） | AD1: 住戸用自動火災報知設備及び共同住宅用非常警報設備
A2: 工事整備対象設備等着工届出書 | AD2: 住戸用自動火災報知設備
AD3: 自動火災報知設備
B4: 令和 年 月 日 | AD4: 共同住宅用自動火災報知設備
B5: =表紙!U5 | T5: 担当消防署 | U5: 浜松市消防署長 殿 | AM5: ※受講期限（講習区分ごと）
J7: 届 出 者 | AC7: 担当者 | AD7: 住所 | AE7: 交付年月日 | AF7: 交付番号 | AG7: 講習日 | AH7: 講習期限 | AJ7: 受講地 | AK7: 交付 | AM7: (1) 消防設備士免状の交付を受けた日以降における最初の4月1日から2年以内
K8: 住 所 | L8: =VLOOKUP($U$8,$AC$8:$AK$11,2,FALSE) | T8: 届出者 | U8: 戸田 健仁 | AC8: 河合 佑樹 | AD8: 愛知県尾張旭市晴丘町東236番地4 | AE8: R5年7月21日 | AF8: 第00324号 | AG8: 令和7年11月 | AJ8: 愛知 | AK8: 愛知 | AM8: (2) 消防設備士講習を受けた日以降における最初の4月1日から5年以内
K9: 氏 名 | L9: =VLOOKUP($U$8,$AC$8:$AK$11,1,FALSE) | AM9: ※期限内に受講していない方は、免状の返納命令に基づく違反点数の措置対象になります。
AC10: 戸田 健仁 | AD10: 愛知県長久手市西原山1-1 ｾﾝﾄｱｰｽ502 | AE10: R5年11月7日 | AF10: 第00448号 | AG10: 令和7年11月 | AJ10: 愛知 | AK10: 愛知
B11: 工事の場所 | J11: =表紙!U11 | T11: 住所 | U11: 静岡県浜松市中央区板屋町547 | AC11: 棚町 征 | AD11: 岐阜県土岐市泉町大富195番地の249 | AE11: H14年10月30日 | AF11: 第00009号 | AG11: 令和元年10月 | AJ11: 愛知 | AK11: 愛知
B12: 工事を行う防火対象物の名称 | J12: =表紙!U12 | T12: 名称 | U12: セラン
B13: 工事整備対象設備等の種類 | J13: =U13 | T13: 種類 | U13: 共同住宅用自動火災報知設備
B14: 工事整備対象設備 | C14: 等の工事施工者 | F14: 住所 | J14: 名古屋市中区栄４丁目１６番３号 山光堂ビル５階
M15: 電話番号 ０５２－２６９－９１００ | T15: 着工日 | U15: 46086 | AA15: =TEXT(U15,"ggg" ) | AB15: =TEXT(U15,"e年" ) | AC15: =TEXT(U15,"m月" ) | AD15: =TEXT(U15,"ｄ日" )
F16: 氏名 法人の場合は名称 及び代表者氏名 | J16: 株式会社 TSCアクセス・プロ | T16: 完了日 | U16: 46093 | AA16: =TEXT(U16,"ggg" ) | AB16: =TEXT(U16,"e年" ) | AC16: =TEXT(U16,"m月" ) | AD16: =TEXT(U16,"ｄ日" )
M17: 代表取締役 中村 勇
A18: 消防設備士 | F18: 免状の 種類及び指定区分 | I18: 種類等 | K18: 交付知事 | M18: 交付年月日 | O18: 講習受講状況
M19: 交付番号 | O19: 受講地 | Q19: 講習年月
I20: 甲・乙 | J20: 種４類 | L20: 都道 | M20: =VLOOKUP($U$8,$AC$8:$AK$11,3,FALSE) | P20: 都道 | Q20: =VLOOKUP($U$8,$AC$8:$AK$11,5,FALSE)
K21: =VLOOKUP($U$8,$AC$8:$AK$11,9,FALSE) | L21: 府県 | M21: =VLOOKUP($U$8,$AC$8:$AK$11,4,FALSE) | O21: =VLOOKUP($U$8,$AC$8:$AK$11,8,FALSE) | P21: 府県
B22: 工事の種別 | J22: １ 施設 ２ 増設 ３ 移設 ４ 取替え
J23: ５ 改造 ６ その他
B24: 着工予定日 | I24: =表紙!U15 | M24: 完 成 予 定 日 | O24: =表紙!U16
A25: ※ 受 付 欄 | K25: ※ 経 過 欄
B32: 備考 | D32: １ この用紙の大きさは、日本産業規格A４とすること。
D33: ２ 工事の種別の欄は、該当する事項を○印で囲むこと。
D34: ３ ※印の欄には、記入しないこと。

Sheet 面積概要表
A1: 別記様式１
E2: 防火対象物 | G2: の概要表
E3: 製造所等
A5: 建 築 物 の 概 要 | O5: 用途 | P5: ５項ロ 共同住宅
A6: 名 称 | C6: =表紙!U12 | G6: 所 在 地 | I6: =表紙!U11 | AA6: =TEXT(P7,)&TEXT(Q7,"##")&TEXT(R7,) | AC6: =TEXT(AA6,)&" "&TEXT(AA7,)&" "&TEXT(AA8,)
A7: 用 途 | C7: =P5 | E7: 階数（階層） | G7: =面積概要表!AC6 | O7: 階層 | P7: 地上 | Q7: 14 | R7: 階 | S7: 地下 | T7: -- | U7: 階 | V7: 塔屋 | W7: -- | X7: 階 | AA7: =TEXT(S7,)&TEXT(T7,"##")&TEXT(U7,)
A8: 主要構造部 | C8: 耐火構造・準耐火構造・その他（ ） | I8: 延べ床面積 | L8: =IF(P8="","㎡",P8) | O8: 延べ床面積 | R8: ㎡ | AA8: =TEXT(V7,)&TEXT(W7,"##")&TEXT(X7,)
A9: 階別 | B9: 床面積 （㎡） | D9: 用途また室名 | F9: 構造 | H9: 内装仕上げ | L9: 特記事項
H10: 天井 | J10: 壁 | P10: 床面積 | Q10: 用途または室名 | T10: 構造
A11: =IF(1<=Q7,"1階",IF($W$7="","","塔屋")) | B11: =IF(P11="","",P11&"㎡") | D11: =IF(Q11="","",Q11) | F11: =T11 | H11: 既設変更無 | J11: 既設変更無 | O11: =IF(1<=Q7,"1階",IF($W$7="","","塔屋")) | Q11: エントランス・住戸 | T11: 鉄筋コンクリート
A12: =IF(2<=$Q$7,"2階",IF($W$7="","","塔屋")) | B12: =IF(P12="","",P12&"㎡") | D12: =IF(Q12="","",Q12) | F12: =IF($A12="","",F11) | H12: =IF($A12="","",H11) | J12: =IF($A12="","",J11) | O12: =IF(2<=$Q$7,"2階",IF($W$7="","","塔屋")) | Q12: 住戸
A13: =IF(3<=$Q$7,"3階",IF(A12="","",IF(A12="塔屋","",IF($W$7=1,"塔屋","")))) | B13: =IF(P13="","",P13&"㎡") | D13: =IF(Q13="","",Q13) | F13: =IF($A13="","",F12) | H13: =IF($A13="","",H12) | J13: =IF($A13="","",J12) | O13: =IF(3<=$Q$7,"3階",IF(O12="","",IF(O12="塔屋","",IF($W$7=1,"塔屋","")))) | Q13: 住戸
A14: =IF(4<=$Q$7,"4階",IF(A13="","",IF(A13="塔屋","",IF($W$7=1,"塔屋","")))) | B14: =IF(P14="","",P14&"㎡") | D14: =IF(Q14="","",Q14) | F14: =IF($A14="","",F13) | H14: =IF($A14="","",H13) | J14: =IF($A14="","",J13) | O14: =IF(4<=$Q$7,"4階",IF(O13="","",IF(O13="塔屋","",IF($W$7=1,"塔屋","")))) | Q14: 住戸
A15: =IF(5<=$Q$7,"5階",IF(A14="","",IF(A14="塔屋","",IF($W$7=1,"塔屋","")))) | B15: =IF(P15="","",P15&"㎡") | D15: =IF(Q15="","",Q15) | F15: =IF($A15="","",F14) | H15: =IF($A15="","",H14) | J15: =IF($A15="","",J14) | O15: =IF(5<=$Q$7,"5階",IF(O14="","",IF(O14="塔屋","",IF($W$7=1,"塔屋","")))) | Q15: 住戸
A16: =IF(6<=$Q$7,"6階",IF(A15="","",IF(A15="塔屋","",IF($W$7=1,"塔屋","")))) | B16: =IF(P16="","",P16&"㎡") | D16: =IF(Q16="","",Q16) | F16: =IF($A16="","",F15) | H16: =IF($A16="","",H15) | J16: =IF($A16="","",J15) | O16: =IF(6<=$Q$7,"6階",IF(O15="","",IF(O15="塔屋","",IF($W$7=1,"塔屋","")))) | Q16: 住戸
A17: =IF(7<=$Q$7,"7階",IF(A16="","",IF(A16="塔屋","",IF($W$7=1,"塔屋","")))) | B17: =IF(P17="","",P17&"㎡") | D17: =IF(Q17="","",Q17) | F17: =IF($A17="","",F16) | H17: =IF($A17="","",H16) | J17: =IF($A17="","",J16) | O17: =IF(7<=$Q$7,"7階",IF(O16="","",IF(O16="塔屋","",IF($W$7=1,"塔屋","")))) | Q17: 住戸
A18: =IF(8<=$Q$7,"8階",IF(A17="","",IF(A17="塔屋","",IF($W$7=1,"塔屋","")))) | B18: =IF(P18="","",P18&"㎡") | D18: =IF(Q18="","",Q18) | F18: =IF($A18="","",F17) | H18: =IF($A18="","",H17) | J18: =IF($A18="","",J17) | O18: =IF(8<=$Q$7,"8階",IF(O17="","",IF(O17="塔屋","",IF($W$7=1,"塔屋","")))) | Q18: 住戸
A19: =IF(9<=$Q$7,"9階",IF(A18="","",IF(A18="塔屋","",IF($W$7=1,"塔屋","")))) | B19: =IF(P19="","",P19&"㎡") | D19: =IF(Q19="","",Q19) | F19: =IF($A19="","",F18) | H19: =IF($A19="","",H18) | J19: =IF($A19="","",J18) | O19: =IF(9<=$Q$7,"9階",IF(O18="","",IF(O18="塔屋","",IF($W$7=1,"塔屋","")))) | Q19: 住戸
A20: =IF(10<=$Q$7,"10階",IF(A19="","",IF(A19="塔屋","",IF($W$7=1,"塔屋","")))) | B20: =IF(P20="","",P20&"㎡") | D20: =IF(Q20="","",Q20) | F20: =IF($A20="","",F19) | H20: =IF($A20="","",H19) | J20: =IF($A20="","",J19) | O20: =IF(10<=$Q$7,"10階",IF(O19="","",IF(O19="塔屋","",IF($W$7=1,"塔屋","")))) | Q20: 住戸
A21: =IF(11<=$Q$7,"11階",IF(A20="","",IF(A20="塔屋","",IF($W$7=1,"塔屋","")))) | B21: =IF(P21="","",P21&"㎡") | D21: =IF(Q21="","",Q21) | F21: =IF($A21="","",F20) | H21: =IF($A21="","",H20) | J21: =IF($A21="","",J20) | O21: =IF(11<=$Q$7,"11階",IF(O20="","",IF(O20="塔屋","",IF($W$7=1,"塔屋","")))) | Q21: 住戸
A22: =IF(12<=$Q$7,"12階",IF(A21="","",IF(A21="塔屋","",IF($W$7=1,"塔屋","")))) | B22: =IF(P22="","",P22&"㎡") | D22: =IF(Q22="","",Q22) | F22: =IF($A22="","",F21) | H22: =IF($A22="","",H21) | J22: =IF($A22="","",J21) | O22: =IF(12<=$Q$7,"12階",IF(O21="","",IF(O21="塔屋","",IF($W$7=1,"塔屋","")))) | Q22: 住戸
A23: =IF(13<=$Q$7,"13階",IF(A22="","",IF(A22="塔屋","",IF($W$7=1,"塔屋","")))) | B23: =IF(P23="","",P23&"㎡") | D23: =IF(Q23="","",Q23) | F23: =IF($A23="","",F22) | H23: =IF($A23="","",H22) | J23: =IF($A23="","",J22) | O23: =IF(13<=$Q$7,"13階",IF(O22="","",IF(O22="塔屋","",IF($W$7=1,"塔屋","")))) | Q23: 住戸
A24: =IF(14<=$Q$7,"14階",IF(A23="","",IF(A23="塔屋","",IF($W$7=1,"塔屋","")))) | B24: =IF(P24="","",P24&"㎡") | D24: =IF(Q24="","",Q24) | F24: =IF($A24="","",F23) | H24: =IF($A24="","",H23) | J24: =IF($A24="","",J23) | O24: =IF(14<=$Q$7,"14階",IF(O23="","",IF(O23="塔屋","",IF($W$7=1,"塔屋","")))) | Q24: 住戸
A25: =IF(15<=$Q$7,"15階",IF(A24="","",IF(A24="塔屋","",IF($W$7=1,"塔屋","")))) | B25: =IF(P25="","",P25&"㎡") | D25: =IF(Q25="","",Q25) | F25: =IF($A25="","",F24) | H25: =IF($A25="","",H24) | J25: =IF($A25="","",J24) | O25: =IF(15<=$Q$7,"15階",IF(O24="","",IF(O24="塔屋","",IF($W$7=1,"塔屋",""))))
A26: そ の 他
A31: 備考 １ この用紙の大きさは、日本産業規格Ａ４とすること。
A32: ２ 消防用設備等の設置に係る階について、各階ごとに記入すること。

Sheet 共用部【その1】
A1: 別記様式５ | M1: 【共用部】 | P1: 左のシートはプルダウンのみ操作 | AB1: 触るな危険
A2: 自 動 火 災 報 知 設 備 の 概 要 表 | M2: （その１） | P2: 入力フォーム | AB2: 差動式 | AC2: （ ) | AE2: 〇 | AF2: 特種 | AG2: パナソニック㈱
A3: 感 知 器 | B3: 機 種 | I3: 蓄積 | J3: 自動 | K3: 遠隔 | L3: 種別 | M3: 個数 | P3: 機種 | T3: 蓄積 | U3: 自動 | V3: 遠隔 | W3: 種別 | X3: 個数 | AB3: 定温式 | AC3: （60℃防水) | AF3: 1種 | AG3: ニッタン(株) | AI3: (自己保持)
B4: =IF(P4="","",P4&" "&Q4&" "&Q5) | G4: =IF(R4="","",R4) | I4: =IF(T4="","",T4) | J4: =IF(U4="","",U4) | K4: =IF(V4="","",V4) | L4: =IF(W4="","",W4) | M4: =IF(X4="","",X4) | P4: 差動式 | Q4: スポット型 | R4: （ ) | W4: 2種 | X4: 8 | AB4: 光電式 | AC4: （70℃防水) | AF4: 2種 | AG4: 能美防災㈱ | AI4: (3線式)
B5: =IF(P4="","","型 式 番 号 感 第") | E5: =IF(P4="","",TEXT(R5,"##")&"～"&TEXT(T5,"##")&"号") | G5: =IF(P4="","","製造会社名") | I5: =IF(V5="","",V5) | Q5: (自己保持) | R5: 2021 | S5: ～ | T5: 35 | V5: パナソニック㈱ | AC5: （75℃防水) | AF5: 3種 | AG5: ホーチキ㈱ | AI5: (3線式 自己保持)
B6: =IF(P6="","",P6&" "&Q6&" "&Q7) | G6: =IF(R6="","",R6) | I6: =IF(T6="","",T6) | J6: =IF(U6="","",U6) | K6: =IF(V6="","",V6) | L6: =IF(W6="","",W6) | M6: =IF(X6="","",X6) | P6: 光電式 | Q6: スポット型 | R6: （ ) | W6: 2種 | X6: 1 | AC6: （65℃防水) | AG6: JVCケンウッド ㈱パナソニック
B7: =IF(P6="","","型 式 番 号 感 第") | E7: =IF(P6="","",TEXT(R7,"##")&"～"&TEXT(T7,"##")&"号") | G7: =IF(P6="","","製造会社名") | I7: =IF(V7="","",V7) | R7: 24 | S7: ～ | T7: 29 | V7: パナソニック㈱ | AC7: （100℃防水)
B8: =IF(P8="","",P8&" "&Q8&" "&Q9) | G8: =IF(R8="","",R8) | I8: =IF(T8="","",T8) | J8: =IF(U8="","",U8) | K8: =IF(V8="","",V8) | L8: =IF(W8="","",W8) | M8: =IF(X8="","",X8) | P8: 定温式 | Q8: スポット型 | R8: （60℃防水) | W8: 特種 | X8: 11
B9: =IF(P8="","","型 式 番 号 感 第") | E9: =IF(P8="","",TEXT(R9,"##")&"～"&TEXT(T9,"##")&"号") | G9: =IF(P8="","","製造会社名") | I9: =IF(V9="","",V9) | Q9: (自己保持) | R9: 17 | S9: ～ | T9: 2 | V9: パナソニック㈱
B10: =IF(P10="","",P10&" "&Q10&" "&Q11) | G10: =IF(R10="","",R10) | I10: =IF(T10="","",T10) | J10: =IF(U10="","",U10) | K10: =IF(V10="","",V10) | L10: =IF(W10="","",W10) | M10: =IF(X10="","",X10) | Q10: スポット型
B11: =IF(P10="","","型 式 番 号 感 第") | E11: =IF(P10="","",TEXT(R11,"##")&"～"&TEXT(T11,"##")&"号") | G11: =IF(P10="","","製造会社名") | I11: =IF(V11="","",V11) | S11: ～
B12: =IF(P12="","",P12&" "&Q12&" "&Q13) | G12: =IF(R12="","",R12) | I12: =IF(T12="","",T12) | J12: =IF(U12="","",U12) | K12: =IF(V12="","",V12) | L12: =IF(W12="","",W12) | M12: =IF(X12="","",X12) | Q12: スポット型
B13: =IF(P12="","","型 式 番 号 感 第") | E13: =IF(P12="","",TEXT(R13,"##")&"～"&TEXT(T13,"##")&"号") | G13: =IF(P12="","","製造会社名") | I13: =IF(V13="","",V13) | S13: ～
B14: =IF(P14="","",P14&" "&Q14&" "&Q15) | G14: =IF(R14="","",R14) | I14: =IF(T14="","",T14) | J14: =IF(U14="","",U14) | K14: =IF(V14="","",V14) | L14: =IF(W14="","",W14) | M14: =IF(X14="","",X14) | Q14: スポット型
B15: =IF(P14="","","型 式 番 号 感 第") | E15: =IF(P14="","",TEXT(R15,"##")&"～"&TEXT(T15,"##")&"号") | G15: =IF(P14="","","製造会社名") | I15: =IF(V15="","",V15) | S15: ～
B16: =IF(P16="","",P16&" "&Q16&" "&Q17) | G16: =IF(R16="","",R16) | I16: =IF(T16="","",T16) | J16: =IF(U16="","",U16) | K16: =IF(V16="","",V16) | L16: =IF(W16="","",W16) | M16: =IF(X16="","",X16) | Q16: スポット型
B17: =IF(P16="","","型 式 番 号 感 第") | E17: =IF(P16="","",TEXT(R17,"##")&"～"&TEXT(T17,"##")&"号") | G17: =IF(P16="","","製造会社名") | I17: =IF(V17="","",V17) | S17: ～
B18: =IF(P18="","",P18&" "&Q18&" "&Q19) | G18: =IF(R18="","",R18) | I18: =IF(T18="","",T18) | J18: =IF(U18="","",U18) | K18: =IF(V18="","",V18) | L18: =IF(W18="","",W18) | M18: =IF(X18="","",X18) | Q18: スポット型
B19: =IF(P18="","","型 式 番 号 感 第") | E19: =IF(P18="","",TEXT(R19,"##")&"～"&TEXT(T19,"##")&"号") | G19: =IF(P18="","","製造会社名") | I19: =IF(V19="","",V19) | S19: ～
B20: =IF(P20="","",P20&" "&Q20&" "&Q21) | G20: =IF(R20="","",R20) | I20: =IF(T20="","",T20) | J20: =IF(U20="","",U20) | K20: =IF(V20="","",V20) | L20: =IF(W20="","",W20) | M20: =IF(X20="","",X20) | Q20: スポット型
B21: =IF(P20="","","型 式 番 号 感 第") | E21: =IF(P20="","",TEXT(R21,"##")&"～"&TEXT(T21,"##")&"号") | G21: =IF(P20="","","製造会社名") | I21: =IF(V21="","",V21) | S21: ～
B22: =IF(P22="","",P22&" "&Q22&" "&Q23) | G22: =IF(R22="","",R22) | I22: =IF(T22="","",T22) | J22: =IF(U22="","",U22) | K22: =IF(V22="","",V22) | L22: =IF(W22="","",W22) | M22: =IF(X22="","",X22) | Q22: スポット型
B23: =IF(P22="","","型 式 番 号 感 第") | E23: =IF(P22="","",TEXT(R23,"##")&"～"&TEXT(T23,"##")&"号") | G23: =IF(P22="","","製造会社名") | I23: =IF(V23="","",V23) | S23: ～
A24: 発 信 機 | C24: 屋内型 | D24: =TEXT(P24,)&"型" | E24: =TEXT(R24,"＃＃")&"級" | F24: =TEXT(T24,"＃＃")&"個" | G24: =IF(W24="","型式番号 発第 号","型式番号 発第"&W24&"号") | J24: 製造会社名 | L24: =IF(Z24="","",Z24) | O24: 屋内型 | Q24: 型 | R24: =IF(P24="","","1") | S24: 級 | U24: 個 | V24: 発第 | X24: 製造会社名
C25: 屋外型 | D25: =TEXT(P25,)&"型" | E25: =TEXT(R25,"＃＃")&"級" | F25: =TEXT(T25,"＃＃")&"個" | G25: =IF(W25="","型式番号 発第 号","型式番号 発第"&W25&"号") | J25: 製造会社名 | L25: =IF(Z25="","",Z25) | O25: 屋外型 | Q25: 型 | S25: 級 | U25: 個 | V25: 発第 | X25: 製造会社名
A26: 表 示 灯 | C26: ="DC(AC) "&TEXT(P26,"##")&"V "&TEXT(R26,"##")&"ｍA "&TEXT(T26,"##")&"個" | O26: 表示灯 | Q26: V | R26: =IF(P26="","","9") | S26: ｍA | U26: 個
A27: 中 継 器 | B27: 種 別 | G27: 回線数 | H27: 電 源 供 給 方 式 | M27: 設置台数 | P27: 24 | R27: pana9mA
B28: 自動･遠隔･アナログ･その他（型式番号 中第 号） | H28: 専用（予備電源 Ｖ AH）･受信機･その他（ ）
B29: 自動･遠隔･アナログ･その他（型式番号 中第 号） | H29: 専用（予備電源 Ｖ AH）･受信機･その他（ ）
B30: 自動･遠隔･アナログ･その他（型式番号 中第 号） | H30: 専用（予備電源 Ｖ AH）･受信機･その他（ ）
B31: 自動･遠隔･アナログ･その他（型式番号 中第 号） | H31: 専用（予備電源 Ｖ AH）･受信機･その他（ ）
B32: 自動･遠隔･アナログ･その他（型式番号 中第 号） | H32: 専用（予備電源 Ｖ AH）･受信機･その他（ ）
B33: 自動･遠隔･アナログ･その他（型式番号 中第 号） | H33: 専用（予備電源 Ｖ AH）･受信機･その他（ ）
B34: 自動･遠隔･アナログ･その他（型式番号 中第 号） | H34: 専用（予備電源 Ｖ AH）･受信機･その他（ ）
B35: 自動･遠隔･アナログ･その他（型式番号 中第 号） | H35: 専用（予備電源 Ｖ AH）･受信機･その他（ ）
B36: 自動･遠隔･アナログ･その他（型式番号 中第 号） | H36: 専用（予備電源 Ｖ AH）･受信機･その他（ ）
B37: 自動･遠隔･アナログ･その他（型式番号 中第 号） | H37: 専用（予備電源 Ｖ AH）･受信機･その他（ ）
B38: 製 造 会 社 名 | G38: =IF(R38="","",R38) | P38: 製造会社名

Sheet 共用部【その2】 
A1: 別記様式５ | M1: 【共用部】
A2: 自 動 火 災 報 知 設 備 の 概 要 表 | M2: （その２） | P2: 入力フォーム | AC2: 認評音第
A3: 受 信 機 | B3: 蓄積式・二信号式・アナログ式・自動試験機能付き・遠隔試験機能付き・その他（ ） | O3: P・GP | R3: 級 | S3: 回線 | U3: / | W3: 自火報点数 | Z3: 2 | AA3: 点 | AC3: 認評放第
B4: ="Ｐ･GP型"&Q3&"級 "&U3&" 回線 "&" Ｒ･GR型 自火報点数 "&Z3&"点 その他（ ）点数 点 予備点数 点" | O4: 台数 | Q4: 1 | R4: 台
B5: =IF(R5="","予備電源（DC Ｖ AH）","予備電源（DC "&R5&"V " &T5&"AH）") | F5: 設置場所 | H5: =IF(Y5="","",Y5) | O5: 予備電源 | Q5: DC | R5: 24 | S5: V | T5: 3.5 | U5: Ah | W5: 設置場所 | Y5: 管理人室 | AC5: 統合盤点数は警戒区域数？
B6: 型式番号 | C6: ="受第"&TEXT(Q6,"##")&"～"&TEXT(T6,"##")&"号" | F6: 製造会社名 | H6: =IF(Y6="","",Y6) | O6: 型式番号 | Q6: 2020 | S6: ～ | T6: 6～1 | V6: 号 | W6: 会社名 | Y6: パナソニック㈱
A7: 表示器 | C7: ／ 回線 台 自火報点数 点 その他点数 点 予備点数 点
C8: ／ 回線 台 自火報点数 点 その他点数 点 予備点数 点
A9: 電 源 | B9: 常用電源 | D9: 単相・三相 AC 100 Ｖ 非常電源専用受電設備回路・電灯回路・動力回路
D10: DC Ｖ AH 充電方式（トリクル・浮動） 使用別（専用・共用（ ））
B11: 非常電源 | D11: 非常電源専用受電設備 単相・三相 AC Ｖ
D12: 蓄電池設備 DC Ｖ AH 充電方式（トリクル・浮動） 使用別（専用・共用（ ））
A13: 音 響 装 置 | B13: 主音響装置 （内蔵されている物は除く） | D13: ベル・サイレン・電子ブザー・音声合成・その他（ ） | O13: 鐘径 | S13: ｍｍ
D14: =IF(Q13="","鐘径 mm","鐘径 "&Q13&" mm") | F14: =IF(Q14=""," 定格 DC Ｖ mA 個 dB"," 定格 DC "&Q14&"V " &S14&"mA "&U14&"個 "&W14&"dB") | O14: 定格 | P14: DC | R14: V | T14: mA | V14: 個 | X14: dB
D15: =IF(COUNTA(Q15,S15)=0,"型式番号（ 号）","型式番号 ("&IF(Q15="","",O15&Q15&"号")&IF(S15="",""," "&S15&"号")&"）") | H15: 製造会社名 | J15: =IF(W15="","",W15) | O15: 認評放第 | U15: 会社名
B16: 地区音響装置 | D16: =IF(COUNTA(Q16,S16)=0,"型式番号（ 号）","型式番号 ("&IF(Q16="","",O16&Q16&"号")&IF(S16="",""," "&S16&"号")&"）") | I16: 製造会社名 | K16: =IF(W16="","",W16) | O16: 認評放第 | U16: 会社名
D17: ベル・サイレン・電子ブザー・スピーカー・その他（ ） | O17: 鐘径(ベル） | S17: ｍｍ
D18: =IF(Q17="","鐘径 mm","鐘径 "&Q17&" mm") | F18: =IF(Q18="","定格 DC Ｖ mA 個 dB"," 定格 DC "&Q18&"V "&S18&"mA "&U18&"個 "&W18&"dB"&Q19) | O18: 定格 | P18: DC | T18: mA | V18: 個 | X18: dB
B19: 音声切替装置 | D19: 型式番号（ 号） DC Ｖ | I19: 製造会社名 | O19: 備考（台数など）
D20: 常用電源 | E20: 単相 AC Ｖ 非常電源専用受電設備回路・電灯回路
D21: 非常電源 | E21: 蓄電池設備 DC Ｖ AH 充電方式（トリクル・浮動）
A22: 配 線 | B22: 常用電源回路 | D22: ケーブル露出・電線管露出・電線管埋設・その他（ ）
B23: 非常電源回路 | D23: 耐火電線・電線管露出・電線管埋設・その他（ ）
B24: 警報回路 | D24: 耐火電線・電線管露出・電線管埋設・その他（ ）
B25: その他回路 | D25: IV電線・ケーブル露出・電線管露出・電線管埋設・その他（ ）
A26: 関連設備 | D26: =IF(P26="","",P26) | O26: 関連設備 | P26: インターホン設備
D27: =IF(P27="","",P27)
A28: 工事者区分 | D28: 電源工事
D29: 配線工事
D30: 配線工事
D31: 配線工事
D32: 機器の取付工事 | F32: 株式会社 ＴＳＣアクセス・プロ
A33: そ の 他
O34: 表示灯容量計算 = 1/0.8×K×I（K＝2.3）
O35: =" = 1/0.8×"&S40&"×2.3×"&S39
O36: =" = "&W41&"Ah ＜"&W39
O37: =IF(W39="1.2Ah","非常警報設備交換 品番：BV13422H 認評非第13～21号","非常警報設備交換 品番：BV13412H 認評非第13～21号")
A39: 備考 １ この用紙の大きさは、日本産業規格Ａ４とすること。 | P39: 表示灯台数 | S39: 12 | U39: 台 | V39: ⇒ | W39: =IF(S41<=0.45,"0.45Ah","1.2Ah")
A40: ２ 選択肢の併記してある欄は、該当事項を○印で囲むこと。 | P40: 消費電流 | S40: 0.009 | U40: A | V40: 9ｍA
A41: ３ 感知器記入欄の（ ）内は、その機能又は性能を記入すること。 | P41: 計算式入力済み | S41: =1/0.8*S40*2.3*S39 | U41: Ah | W41: =ROUND(S41,3) | Y41: 0.276
...

Sheet 住戸部【その1】
A1: 別記様式５ | M1: 【住戸部】 | P1: 左のシートはプルダウンのみ操作 | AB1: 触るな危険
A2: 自 動 火 災 報 知 設 備 の 概 要 表 | M2: （その１） | P2: 入力フォーム | AB2: 差動式 | AC2: （ ) | AE2: 〇 | AF2: 特種 | AG2: パナソニック㈱
A3: 感 知 器 | B3: 機 種 | I3: 蓄積 | J3: 自動 | K3: 遠隔 | L3: 種別 | M3: 個数 | P3: 機種 | T3: 蓄積 | U3: 自動 | V3: 遠隔 | W3: 種別 | X3: 個数 | AB3: 定温式 | AC3: （60℃防水) | AF3: 1種 | AG3: ニッタン
B4: =IF(P4="","",P4&" "&Q4) | G4: =IF(R4="","",R4) | I4: =IF(T4="","",T4) | J4: =IF(U4="","",U4) | K4: =IF(V4="","",V4) | L4: =IF(W4="","",W4) | M4: =IF(X4="","",X4) | P4: 定温式 | Q4: スポット型 | R4: （60℃防水) | V4: 〇 | W4: 特種 | X4: 49 | Z4: 601号室（差5.定1） | AB4: 光電式 | AC4: （70℃防水) | AF4: 2種 | AG4: 能美防災
B5: =IF(P4="","","型 式 番 号 感 第") | E5: =IF(P4="","",TEXT(R5,"##")&"～"&TEXT(T5,"##")&"号") | G5: =IF(P4="","","製造会社名") | I5: =IF(V5="","",V5) | Q5: 感第 | R5: 25 | S5: ～ | T5: 3 | U5: 号 | V5: パナソニック㈱ | Z5: 1402号室(差6.定1） | AC5: （75℃防水) | AF5: 3種 | AG5: ホーチキ㈱
B6: =IF(P6="","",P6&" "&Q6) | G6: =IF(R6="","",R6) | I6: =IF(T6="","",T6) | J6: =IF(U6="","",U6) | K6: =IF(V6="","",V6) | L6: =IF(W6="","",W6) | M6: =IF(X6="","",X6) | P6: 差動式 | Q6: スポット型 | R6: （ ) | V6: 〇 | W6: 2種 | X6: 224 | AC6: （65℃防水)
B7: =IF(P6="","","型 式 番 号 感 第") | E7: =IF(P6="","",TEXT(R7,"##")&"～"&TEXT(T7,"##")&"号") | G7: =IF(P6="","","製造会社名") | I7: =IF(V7="","",V7) | Q7: 感第 | R7: 25 | S7: ～ | T7: 4 | U7: 号 | V7: パナソニック㈱
B8: =IF(P8="","",P8&" "&Q8) | G8: =IF(R8="","",R8) | I8: =IF(T8="","",T8) | J8: =IF(U8="","",U8) | K8: =IF(V8="","",V8) | L8: =IF(W8="","",W8) | M8: =IF(X8="","",X8) | Q8: スポット型
B9: =IF(P8="","","型 式 番 号 感 第") | E9: =IF(P8="","",TEXT(R9,"##")&"～"&TEXT(T9,"##")&"号") | G9: =IF(P8="","","製造会社名") | I9: =IF(V9="","",V9) | Q9: 感第 | S9: ～ | U9: 号
B10: =IF(P10="","",P10&" "&Q10) | G10: =IF(R10="","",R10) | I10: =IF(T10="","",T10) | J10: =IF(U10="","",U10) | K10: =IF(V10="","",V10) | L10: =IF(W10="","",W10) | M10: =IF(X10="","",X10) | Q10: スポット型
B11: =IF(P10="","","型 式 番 号 感 第") | E11: =IF(P10="","",TEXT(R11,"##")&"～"&TEXT(T11,"##")&"号") | G11: =IF(P10="","","製造会社名") | I11: =IF(V11="","",V11) | S11: ～
B12: =IF(P12="","",P12&" "&Q12) | G12: =IF(R12="","",R12) | I12: =IF(T12="","",T12) | J12: =IF(U12="","",U12) | K12: =IF(V12="","",V12) | L12: =IF(W12="","",W12) | M12: =IF(X12="","",X12) | Q12: スポット型
B13: =IF(P12="","","型 式 番 号 感 第") | E13: =IF(P12="","",TEXT(R13,"##")&"～"&TEXT(T13,"##")&"号") | G13: =IF(P12="","","製造会社名") | I13: =IF(V13="","",V13) | S13: ～ | U13: 号
B14: =IF(P14="","",P14&" "&Q14) | G14: =IF(R14="","",R14) | I14: =IF(T14="","",T14) | J14: =IF(U14="","",U14) | K14: =IF(V14="","",V14) | L14: =IF(W14="","",W14) | M14: =IF(X14="","",X14) | Q14: スポット型
B15: =IF(P14="","","型 式 番 号 感 第") | E15: =IF(P14="","",TEXT(R15,"##")&"～"&TEXT(T15,"##")&"号") | G15: =IF(P14="","","製造会社名") | I15: =IF(V15="","",V15) | S15: ～ | U15: 号
B16: =IF(P16="","",P16&" "&Q16) | G16: =IF(R16="","",R16) | I16: =IF(T16="","",T16) | J16: =IF(U16="","",U16) | K16: =IF(V16="","",V16) | L16: =IF(W16="","",W16) | M16: =IF(X16="","",X16) | Q16: スポット型
B17: =IF(P16="","","型 式 番 号 感 第") | E17: =IF(P16="","",TEXT(R17,"##")&"～"&TEXT(T17,"##")&"号") | G17: =IF(P16="","","製造会社名") | I17: =IF(V17="","",V17) | S17: ～ | U17: 号
B18: =IF(P18="","",P18&" "&Q18) | G18: =IF(R18="","",R18) | I18: =IF(T18="","",T18) | J18: =IF(U18="","",U18) | K18: =IF(V18="","",V18) | L18: =IF(W18="","",W18) | M18: =IF(X18="","",X18) | Q18: スポット型
B19: =IF(P18="","","型 式 番 号 感 第") | E19: =IF(P18="","",TEXT(R19,"##")&"～"&TEXT(T19,"##")&"号") | G19: =IF(P18="","","製造会社名") | I19: =IF(V19="","",V19) | S19: ～ | U19: 号
B20: =IF(P20="","",P20&" "&Q20) | G20: =IF(R20="","",R20) | I20: =IF(T20="","",T20) | J20: =IF(U20="","",U20) | K20: =IF(V20="","",V20) | L20: =IF(W20="","",W20) | M20: =IF(X20="","",X20) | Q20: スポット型
B21: =IF(P20="","","型 式 番 号 感 第") | E21: =IF(P20="","",TEXT(R21,"##")&"～"&TEXT(T21,"##")&"号") | G21: =IF(P20="","","製造会社名") | I21: =IF(V21="","",V21) | S21: ～ | U21: 号
B22: =IF(P22="","",P22&" "&Q22) | G22: =IF(R22="","",R22) | I22: =IF(T22="","",T22) | J22: =IF(U22="","",U22) | K22: =IF(V22="","",V22) | L22: =IF(W22="","",W22) | M22: =IF(X22="","",X22) | Q22: スポット型
B23: =IF(P22="","","型 式 番 号 感 第") | E23: =IF(P22="","",TEXT(R23,"##")&"～"&TEXT(T23,"##")&"号") | G23: =IF(P22="","","製造会社名") | I23: =IF(V23="","",V23) | S23: ～ | U23: 号
A24: 発 信 機 | C24: 屋内型 | D24: =TEXT(P24,)&"型" | E24: =TEXT(R24,"＃＃")&"級" | F24: =TEXT(T24,"＃＃")&"個" | G24: =IF(W24="","型式番号 発第 号","型式番号 発第"&W24&"号") | J24: 製造会社名 | L24: =IF(Z24="","",Z24) | O24: 屋内型 | Q24: 型 | S24: 級 | U24: 個 | V24: 型式 | X24: 製造会社名
C25: 屋外型 | D25: =TEXT(P25,)&"型" | E25: =TEXT(R25,"＃＃")&"級" | F25: =TEXT(T25,"＃＃")&"個" | G25: =IF(W25="","型式番号 発第 号","型式番号 発第"&W25&"号") | J25: 製造会社名 | L25: =IF(Z25="","",Z25) | O25: 屋外型 | Q25: 型 | S25: 級 | U25: 個 | V25: 型式 | X25: 製造会社名
A26: 表 示 灯 | C26: ="DC(AC) "&TEXT(P26,"##")&"V "&TEXT(R26,"##")&"ｍA "&TEXT(T26,"##")&"個" | O26: 表示灯 | Q26: V | S26: ｍA | U26: 個
A27: 中 継 器 | B27: 種 別 | G27: 回線数 | H27: 電 源 供 給 方 式 | M27: 設置台数
B28: =IF(Q28="","自動･遠隔･アナログ･その他（型式番号 中第 号）","自動･遠隔･アナログ･その他（型式番号 中第 "&Q28&"号）") | G28: =U28 | H28: 専用（予備電源 Ｖ AH）･受信機･その他（ ） | M28: =TEXT(X28,"＃＃")&"台" | P28: 中第 | Q28: 29-10 | R28: 号 | T28: 回線数 | U28: 1/1 | V28: 中継器 | W28: 設置台数 | X28: 49 | Y28: 台 | Z28: 601
B29: 自動･遠隔･アナログ･その他（型式番号 中第 号） | H29: 専用（予備電源 Ｖ AH）･受信機･その他（ ） | Z29: 1402
B30: 自動･遠隔･アナログ･その他（型式番号 中第 号） | H30: 専用（予備電源 Ｖ AH）･受信機･その他（ ）
B31: 自動･遠隔･アナログ･その他（型式番号 中第 号） | H31: 専用（予備電源 Ｖ AH）･受信機･その他（ ）
B32: 自動･遠隔･アナログ･その他（型式番号 中第 号） | H32: 専用（予備電源 Ｖ AH）･受信機･その他（ ）
B33: 自動･遠隔･アナログ･その他（型式番号 中第 号） | H33: 専用（予備電源 Ｖ AH）･受信機･その他（ ）
B34: 自動･遠隔･アナログ･その他（型式番号 中第 号） | H34: 専用（予備電源 Ｖ AH）･受信機･その他（ ）
B35: 自動･遠隔･アナログ･その他（型式番号 中第 号） | H35: 専用（予備電源 Ｖ AH）･受信機･その他（ ）
B36: 自動･遠隔･アナログ･その他（型式番号 中第 号） | H36: 専用（予備電源 Ｖ AH）･受信機･その他（ ）
B37: 自動･遠隔･アナログ･その他（型式番号 中第 号） | H37: 専用（予備電源 Ｖ AH）･受信機･その他（ ）
B38: 製 造 会 社 名 | G38: =IF(R38="","",R38) | P38: 製造会社名 | R38: パナソニック㈱

Sheet 住戸部【その2】
A1: 別記様式５ | M1: 【住戸部】
A2: 自 動 火 災 報 知 設 備 の 概 要 表 | M2: （その２） | P2: 入力フォーム
A3: 受 信 機 | B3: 蓄積式・二信号式・アナログ式・自動試験機能付き・遠隔試験機能付き・その他（ ） | O3: P・GP | Q3: 3 | R3: 級 | S3: 回線 | U3: 1/1
B4: ="Ｐ･GP型"&Q3&"級 "&U3&" 回線 台 Ｒ･GR型 自火報点数 点 その他（ ）点数 点 予備点数 点"
B5: =IF(R5="","予備電源（DC Ｖ AH）","予備電源（DC "&R5&"V " &T5&"AH）") | F5: 設置場所 | H5: =IF(Y5="","",Y5) | O5: 予備電源 | Q5: DC | S5: V | W5: 設置場所 | Y5: 各住戸リビング
B6: 型式番号 | C6: ="受第"&TEXT(Q6,"##")&"～"&TEXT(T6,"##")&"号" | F6: 製造会社名 | H6: =IF(Y6="","",Y6) | O6: 型式番号 | Q6: 2020 | S6: ～ | T6: 2 | V6: 号 | W6: 会社名 | Y6: パナソニック㈱
A7: 表示器 | C7: =IF(U3=""," / 回線 台 自火報点数 点 その他点数 点 予備点数 点"," "&TEXT(U3,"m/d")&" 回線 "&TEXT(Q7,"##")&"台 自火報点数 点 その他点数 点 予備点数 点") | O7: 台数 | Q7: 51 | R7: 台
C8: / 回線 台 自火報点数 点 その他点数 点 予備点数 点
A9: 電 源 | B9: 常用電源 | D9: 単相・三相 AC 100 Ｖ 非常電源専用受電設備回路・電灯回路・動力回路
D10: DC Ｖ AH 充電方式（トリクル・浮動） 使用別（専用・共用（ ））
B11: 非常電源 | D11: 非常電源専用受電設備 単相・三相 AC Ｖ
D12: 蓄電池設備 DC Ｖ AH 充電方式（トリクル・浮動） 使用別（専用・共用（ ））
A13: 音 響 装 置 | B13: 主音響装置 （内蔵されている物は除く） | D13: ベル・サイレン・電子ブザー・音声合成・その他（ ） | O13: 鐘径 | S13: ｍｍ
D14: =IF(Q13="","鐘径 mm","鐘径 "&Q13&" mm") | F14: =IF(Q14=""," 定格 DC Ｖ mA 個 dB"," 定格 DC "&Q14&"V " &S14&"mA "&U14&"個 "&W14&"dB") | O14: 定格 | P14: DC | R14: V | T14: mA | V14: 個 | X14: dB
D15: =IF(COUNTA(Q15,S15)=0,"型式番号（ 号）","型式番号 ("&IF(Q15="","","認評音第 "&Q15&"号")&IF(S15="",""," "&S15&"号")&"）") | H15: 製造会社名 | J15: =IF(W15="","",W15) | O15: 認評音第 | U15: 会社名
B16: 地区音響装置 | D16: =IF(COUNTA(Q16,S16)=0,"型式番号（ 号）","型式番号 ("&IF(Q16="","","認評音第 "&Q16&"号")&IF(S16="",""," "&S16&"号")&"）") | I16: 製造会社名 | K16: =IF(W16="","",W16) | O16: 認評音第 | U16: 会社名
D17: ベル・サイレン・電子ブザー・スピーカー・その他（ ） | O17: 鐘径 | S17: ｍｍ
D18: =IF(Q17="","鐘径 mm","鐘径 "&Q17&" mm") | F18: =IF(Q18=""," 定格 DC Ｖ mA 個 dB"," 定格 DC "&Q18&"V " &S18&"mA "&U18&"個 "&W18&"dB") | O18: 定格 | P18: DC | R18: V | T18: mA | V18: 個 | X18: dB
B19: 音声切替装置 | D19: 型式番号（ 号） DC Ｖ | I19: 製造会社名 | K19: =IF(W19="","",W19) | U19: 会社名
D20: 常用電源 | E20: 単相 AC Ｖ 非常電源専用受電設備回路・電灯回路
D21: 非常電源 | E21: 蓄電池設備 DC Ｖ AH 充電方式（トリクル・浮動）
A22: 配 線 | B22: 常用電源回路 | D22: ケーブル露出・電線管露出・電線管埋設・その他（ ）
B23: 非常電源回路 | D23: 耐火電線・電線管露出・電線管埋設・その他（ ）
B24: 警報回路 | D24: 耐火電線・電線管露出・電線管埋設・その他（ ）
B25: その他回路 | D25: IV電線・ケーブル露出・電線管露出・電線管埋設・その他（ ）
A26: 関連設備 | D26: =IF(P26="","",P26) | O26: 関連設備 | P26: インターホン設備
D27: =IF(P27="","",P27)
A28: 工事者区分 | D28: 電源工事
D29: 配線工事
D30: 配線工事 | P30: メモ
D31: 配線工事 | P31: ※住戸用自動火災報知設備更新工事。
D32: 機器の取付工事 | F32: 株式会社 ＴＳＣアクセス・プロ | P32: 全住戸（17戸）のGP３級受信機・遠隔試験中継器内蔵ドアホン子器交換工事。
A33: そ の 他 | B33: 全住戸（51戸）のGP３級受信機・遠隔試験中継器内蔵ドアホン子器交換工事。
P34: 全住戸（45戸）のGP３級受信機・遠隔試験中継器内蔵ドアホン子器交換工事。
P35: 管理人室のGP３級受信機・遠隔試験中継器内蔵ドアホン子器交換工事。
P36: GP3級受信機品番：SHGT67132W 受第18～17号
P37: 子器品番：EJ560AN 中第8～19号
A39: 備考 １ この用紙の大きさは、日本産業規格Ａ４とすること。
A40: ２ 選択肢の併記してある欄は、該当事項を○印で囲むこと。
A41: ３ 感知器記入欄の（ ）内は、その機能又は性能を記入すること。
...

Sheet 設置
A1: 別記様式第１号の２の３（第３１条の３関係）
A2: 消 防 用 設 備 等 （ 特 殊 消 防 用 設 備 等 ） 設 置 届 書
S3: 令和 年 月 日
B4: =表紙!U5 | J4: 届出者
J5: ="住 所 "&表紙!U11
J6: ="氏 名 "&表紙!U12&"管理組合"
J8: ="理事長 "&W8 | V8: 理事長
A9: 下記のとおり、消防用設備等（特殊消防用設備等）を設置したので、消防法第１７条の３の２の規定に基づき届け出ます。
A11: 記
A12: 設置者 | C12: 住 所 | F12: 届出者に同じ 電話
C13: 氏 名 | F13: 届出者に同じ
A14: 防火対象物 | B14: 所 在 地 | F14: =" "&表紙!U11
B15: 名 称 | F15: =" "&表紙!U12
B16: 用 途 | F16: 令別表第一（５項）・ロ 共同住宅
B17: 構造・規模 | F17: =" "&面積概要表!F11 | J17: =面積概要表!G7
F18: 床面積 ㎡ | L18: 延べ面積 | O18: =面積概要表!L8
A19: 消防用設備等（特殊消防用設備等）の種類 | F19: =" "&表紙!U13
A20: 工 事 | B20: 種別 | F20: 新設 、 増設 、 移設 、 取替え 、 改造 、 その他（ ）
B21: 施工者 住 所 氏 名 | D21: 住 所 | F21: 名古屋市中区栄4丁目16番3号 山光堂ビル5階
F22: 電話（052）269-9100番
D23: 氏 名 | F23: 株式会社ＴＳＣアクセス・プロ 代表取締役 中村 勇
B24: 消 防 設備士 | D24: 住 所 | F24: =表紙!L8
D25: 氏 名 | F25: =表紙!L9
D26: 免 状 | F26: 種 類 等 | I26: 交 付 知 事 | L26: 交付年月日 | O26: 講 習 受 講 状 況
L27: 交付番号 | O27: 受 講 地 | R27: 受講年月
F28: 甲・乙 | G28: 種４類 | I28: 愛知 | J28: 都 道 | L28: =表紙!M20 | O28: =表紙!O21 | P28: 都 道 | R28: =表紙!Q20
J29: 府 県 | L29: =表紙!M21 | P29: 府 県
A30: 完 成 年 月 日 | F30: 令和 年 月 日
A31: ※ 受 付 欄 | F31: ※ 決 裁 欄 | M31: ※ 備 考
A37: 備考 １ この用紙の大きさは、日本産業規格A４とすること。
A38: ２ 消防用設備等設計図書又は特殊消防用設備等設計図書は、消防用設備等又は特殊消防用設備等
A39: の種類ごとにそれぞれ添付すること。
A40: ３ ※欄には、記入しないこと。

Sheet 共同住宅用自動火災報知設備
A1: 別記様式第33 | R1: ①
A3: 共同住宅用自動火災報知設備試験結果報告書
A5: 試験実施日 令和 年 月 日
H7: 試験実施者
I9: 住 所 | K9: =表紙!L8
I10: 氏 名 | K10: =表紙!L9
A12: 用途 | C12: （ ５ ）項 ロ・共同住宅 | T12: 階数 | V12: 面積概要表 反映
A13: 延べ面積 | C13: =面積概要表!L8 | J13: 階 数 | L13: =面積概要表!AC6 | T13: 延べ面積 | V13: 面積概要表 反映
A14: 住戸数 | C14: 全住戸数 51戸（601,1402号室未施工） | T14: 住戸数 | V14: 住戸部【その2】 反映
A15: 住棟受信機 | D15: 非蓄積式・蓄積式・自動試験機能付き・遠隔試験機能付き・その他（ ）
D16: Ｐ・ＧＰ型 級 回線数 / | I16: Ｒ・ＧＲ型自火報点数 3点・その他点数 点・予備点数 点
D17: 定格電圧 | F17: ＡＣ 100 Ｖ ・ ＤＣ Ｖ
D18: 予備電源 | F18: NiCd・その他（ ） DC 24Ｖ 3.5ＡＨ
A19: 共同住宅用 受 信 機 | D19: 非蓄積式・蓄積式・自動試験機能付き・遠隔試験機能付き・その他（ ）
D20: 定格電圧 | F20: ＡＣ 100 Ｖ ・ ＤＣ Ｖ
D21: 予備電源 | F21: NiCd・その他（ ） Ｖ ＡＨ
A22: 中 継 器 | B22: アナログ式・蓄積式・自動試験機能付・遠隔試験機能付・他（ ）1/1回線 | K22: 予備電源 有 ( V AH)・無 | P22: ="設置台数 "&住戸部【その1】!X28&" 台" | T22: 設置台数 | V22: 住戸部【その1】 反映
B23: アナログ式・蓄積式・自動試験機能付・遠隔試験機能付・他（ ） 回線 | K23: 予備電源 有 ( V AH)・無 | P23: 設置台数 台
B24: アナログ式・蓄積式・自動試験機能付・遠隔試験機能付・他（ ） 回線 | K24: 予備電源 有 ( V AH)・無 | P24: 設置台数 台
B25: アナログ式・蓄積式・自動試験機能付・遠隔試験機能付・他（ ） 回線 | K25: 予備電源 有 ( V AH)・無 | P25: 設置台数 台
B26: アナログ式・蓄積式・自動試験機能付・遠隔試験機能付・他（ ） 回線 | K26: 予備電源 有 ( V AH)・無 | P26: 設置台数 台
A27: 感知器 | B27: 機種 | L27: 自 | M27: 遠 | N27: 種別 | Q27: 個数
B28: 【共用部】
B29: =共用部【その1】!B4&" "&共用部【その1】!D4&共用部【その1】!G4 | L29: =IF(共用部【その1】!J4="","",共用部【その1】!J4) | M29: =IF(共用部【その1】!K4="","",共用部【その1】!K4) | N29: =IF(共用部【その1】!L4="","",共用部【その1】!L4) | Q29: =IF(共用部【その1】!M4="","",共用部【その1】!M4) | V29: 共用部【その1】 反映
B30: =共用部【その1】!B6&" "&共用部【その1】!D6&共用部【その1】!G6 | L30: =IF(共用部【その1】!J6="","",共用部【その1】!J6) | M30: =IF(共用部【その1】!K6="","",共用部【その1】!K6) | N30: =IF(共用部【その1】!L6="","",共用部【その1】!L6) | Q30: =IF(共用部【その1】!M6="","",共用部【その1】!M6)
B31: =共用部【その1】!B8&" "&共用部【その1】!D8&共用部【その1】!G8 | L31: =IF(共用部【その1】!J8="","",共用部【その1】!J8) | M31: =IF(共用部【その1】!K8="","",共用部【その1】!K8) | N31: =IF(共用部【その1】!L8="","",共用部【その1】!L8) | Q31: =IF(共用部【その1】!M8="","",共用部【その1】!M8)
L32: =IF(共用部【その1】!J10="","",共用部【その1】!J10) | M32: =IF(共用部【その1】!K10="","",共用部【その1】!K10) | N32: =IF(共用部【その1】!L10="","",共用部【その1】!L10) | Q32: =IF(共用部【その1】!M10="","",共用部【その1】!M10)
L33: =IF(共用部【その1】!J12="","",共用部【その1】!J12) | M33: =IF(共用部【その1】!K12="","",共用部【その1】!K12) | N33: =IF(共用部【その1】!L12="","",共用部【その1】!L12) | Q33: =IF(共用部【その1】!M12="","",共用部【その1】!M12)
B34: 【専有部】
B35: =住戸部【その1】!B4&" "&住戸部【その1】!D4&住戸部【その1】!G4 | L35: =IF(住戸部【その1】!J4="","",住戸部【その1】!J4) | M35: =IF(住戸部【その1】!K4="","",住戸部【その1】!K4) | N35: =IF(住戸部【その1】!L4="","",住戸部【その1】!L4) | Q35: =IF(住戸部【その1】!M4="","",住戸部【その1】!M4) | V35: 住戸部【その1】 反映
B36: =住戸部【その1】!B6&" "&住戸部【その1】!D6&住戸部【その1】!G6 | L36: =IF(住戸部【その1】!J6="","",住戸部【その1】!J6) | M36: =IF(住戸部【その1】!K6="","",住戸部【その1】!K6) | N36: =IF(住戸部【その1】!L6="","",住戸部【その1】!L6) | Q36: =IF(住戸部【その1】!M6="","",住戸部【その1】!M6)
B37: =住戸部【その1】!B8&" "&住戸部【その1】!D8&住戸部【その1】!G8 | L37: =IF(住戸部【その1】!J8="","",住戸部【その1】!J8) | M37: =IF(住戸部【その1】!K8="","",住戸部【その1】!K8) | N37: =IF(住戸部【その1】!L8="","",住戸部【その1】!L8) | Q37: =IF(住戸部【その1】!M8="","",住戸部【その1】!M8)
B38: =住戸部【その1】!B10&" "&住戸部【その1】!D10&住戸部【その1】!G10 | L38: =IF(住戸部【その1】!J10="","",住戸部【その1】!J10) | M38: =IF(住戸部【その1】!K10="","",住戸部【その1】!K10) | N38: =IF(住戸部【その1】!L10="","",住戸部【その1】!L10) | Q38: =IF(住戸部【その1】!M10="","",住戸部【その1】!M10)
B39: =住戸部【その1】!B12&" "&住戸部【その1】!D12&住戸部【その1】!G12 | L39: =IF(住戸部【その1】!J12="","",住戸部【その1】!J12) | M39: =IF(住戸部【その1】!K12="","",住戸部【その1】!K12) | N39: =IF(住戸部【その1】!L12="","",住戸部【その1】!L12) | Q39: =IF(住戸部【その1】!M12="","",住戸部【その1】!M12)
A40: 音声警報装置等 | D40: 音声警報装置 | G40: Ｌ級 | I40: 個 | K40: Ｍ級 | M40: 個 | O40: Ｓ級 | Q40: 個
D41: 戸外表示器 | G41: ――――――― | O41: 個数 | Q41: =住戸部【その1】!X28 | T41: 個数 | V41: 住戸部【その1】 反映
D42: 放送設備との連動等 | G42: 有 ・ 無 （音声切替装置 有 ・ 無）
A44: 共同住宅用非常警報設備 | R44: ②
A45: 試 験 項 目 | L45: 種別・容量等の内容 | Q45: 結果
A46: 外観試験 | B46: 警戒区域 | F46: 警戒区域の設定 | L46: ――――――― | Q46: 〇 | AG46: 〇
...

Sheet 住戸・共同住宅用自動火災報知設備
A1: 別記様式第34 | R1: ①
A3: 住戸用自動火災報知設備・共同住宅用自動火災報知設備試験結果報告書
A5: 試験実施日 令和 年 月 日
H7: 試験実施者
I9: 住 所 | K9: =表紙!L8
I10: 氏 名 | K10: =表紙!L9
A12: 用途 | C12: （ ５ ）項 ロ・共同住宅
A13: 延べ面積 | C13: =面積概要表!L8 | J13: 階 数 | L13: =面積概要表!AC6
A14: 住戸数 | C14: =" 全住戸数 "&住戸部【その1】!X28&" 戸"
A15: 共同住宅用 受 信 機 | D15: 非蓄積式・蓄積式・自動試験機能付き・遠隔試験機能付き・その他（ ）
D16: 定格電圧 | F16: ＡＣ 100 Ｖ ・ ＤＣ Ｖ
D17: 予備電源 | F17: NiCd・その他（ ） Ｖ ＡＨ
A18: 共用部分に設ける設備 | E18: 住戸用自動火災報知設備・共同住宅用非常警報設備・その他（ ）
A19: 中 継 器 | B19: アナログ式・蓄積式・自動試験機能付・遠隔試験機能付・他（ ）1/1回線 | K19: 予備電源 有 ( V AH)・無 | P19: ="設置台数 "&住戸部【その1】!X28&" 台"
B20: アナログ式・蓄積式・自動試験機能付・遠隔試験機能付・他（ ） 回線 | K20: 予備電源 有 ( V AH)・無 | P20: 設置台数 台
B21: アナログ式・蓄積式・自動試験機能付・遠隔試験機能付・他（ ） 回線 | K21: 予備電源 有 ( V AH)・無 | P21: 設置台数 台
B22: アナログ式・蓄積式・自動試験機能付・遠隔試験機能付・他（ ） 回線 | K22: 予備電源 有 ( V AH)・無 | P22: 設置台数 台
B23: アナログ式・蓄積式・自動試験機能付・遠隔試験機能付・他（ ） 回線 | K23: 予備電源 有 ( V AH)・無 | P23: 設置台数 台
A24: 感 知 器 | B24: 機種 | L24: 自 | M24: 遠 | N24: 種別 | Q24: 個数
B25: 【共用部】
B26: =共用部【その1】!B4&" "&共用部【その1】!D4&共用部【その1】!G4 | L26: =IF(共用部【その1】!J4="","",共用部【その1】!J4) | M26: =IF(共用部【その1】!K4="","",共用部【その1】!K4) | N26: =IF(共用部【その1】!L4="","",共用部【その1】!L4) | Q26: =IF(共用部【その1】!M4="","",共用部【その1】!M4) | T26: 共用部
B27: =共用部【その1】!B6&" "&共用部【その1】!D6&共用部【その1】!G6 | L27: =IF(共用部【その1】!J6="","",共用部【その1】!J6) | M27: =IF(共用部【その1】!K6="","",共用部【その1】!K6) | N27: =IF(共用部【その1】!L6="","",共用部【その1】!L6) | Q27: =IF(共用部【その1】!M6="","",共用部【その1】!M6)
B28: =共用部【その1】!B8&" "&共用部【その1】!D8&共用部【その1】!G8 | L28: =IF(共用部【その1】!J8="","",共用部【その1】!J8) | M28: =IF(共用部【その1】!K8="","",共用部【その1】!K8) | N28: =IF(共用部【その1】!L8="","",共用部【その1】!L8) | Q28: =IF(共用部【その1】!M8="","",共用部【その1】!M8)
B29: =共用部【その1】!B10&" "&共用部【その1】!D10&共用部【その1】!G10 | L29: =IF(共用部【その1】!J10="","",共用部【その1】!J10) | M29: =IF(共用部【その1】!K10="","",共用部【その1】!K10) | N29: =IF(共用部【その1】!L10="","",共用部【その1】!L10) | Q29: =IF(共用部【その1】!M10="","",共用部【その1】!M10)
B30: =共用部【その1】!B12&" "&共用部【その1】!D12&共用部【その1】!G12 | L30: =IF(共用部【その1】!J12="","",共用部【その1】!J12) | M30: =IF(共用部【その1】!K12="","",共用部【その1】!K12) | N30: =IF(共用部【その1】!L12="","",共用部【その1】!L12) | Q30: =IF(共用部【その1】!M12="","",共用部【その1】!M12)
B31: =共用部【その1】!B14&" "&共用部【その1】!D14&共用部【その1】!G14 | N31: =IF(共用部【その1】!L14="","",共用部【その1】!L14) | Q31: =IF(共用部【その1】!M14="","",共用部【その1】!M14)
B32: 【専有部】 | L32: =IF(住戸部【その1】!J4="","",住戸部【その1】!J4)
B33: =住戸部【その1】!B4&" "&住戸部【その1】!D4&住戸部【その1】!G4 | L33: =IF(住戸部【その1】!J6="","",住戸部【その1】!J6) | M33: =IF(住戸部【その1】!K4="","",住戸部【その1】!K4) | N33: =IF(住戸部【その1】!L4="","",住戸部【その1】!L4) | Q33: =IF(住戸部【その1】!M4="","",住戸部【その1】!M4)
B34: =住戸部【その1】!B6&" "&住戸部【その1】!D6&住戸部【その1】!G6 | L34: =IF(住戸部【その1】!J8="","",住戸部【その1】!J8) | M34: =IF(住戸部【その1】!K6="","",住戸部【その1】!K6) | N34: =IF(住戸部【その1】!L6="","",住戸部【その1】!L6) | Q34: =IF(住戸部【その1】!M6="","",住戸部【その1】!M6)
B35: =住戸部【その1】!B10&" "&住戸部【その1】!D10&住戸部【その1】!G10 | L35: =IF(住戸部【その1】!J10="","",住戸部【その1】!J10) | M35: =IF(住戸部【その1】!K10="","",住戸部【その1】!K10) | N35: =IF(住戸部【その1】!L10="","",住戸部【その1】!L10) | Q35: =IF(住戸部【その1】!M10="","",住戸部【その1】!M10)
B36: =住戸部【その1】!B12&" "&住戸部【その1】!D12&住戸部【その1】!G12 | L36: =IF(住戸部【その1】!J12="","",住戸部【その1】!J12) | M36: =IF(住戸部【その1】!K12="","",住戸部【その1】!K12) | N36: =IF(住戸部【その1】!L12="","",住戸部【その1】!L12) | Q36: =IF(住戸部【その1】!M12="","",住戸部【その1】!M12)
A38: 起動装置 | D38: 屋内型 | G38: --個 | M38: 屋外型 | O38: =共用部【その1】!T25 | T38: 発信機
A39: 音声警報装置等 | D39: 音声警報装置 | G39: Ｌ級 | I39: =W39&"個" | K39: Ｍ級 | M39: --個 | O39: Ｓ級 | Q39: --個 | T39: スピーカー数量 | W39: -- | X39: 個
D40: ベル（サイレン) | G40: ="電圧 DC"&'共用部【その2】 '!Q18&"V" | K40: ="電流 "&'共用部【その2】 '!S18&"mA" | O40: 個数 | Q40: ='共用部【その2】 '!U18
D41: 戸外表示器 | G41: ――――――― | O41: 個数 | Q41: =住戸部【その1】!X28
D42: 放送設備との連動等 | G42: 有 ・ 無 （音声切替装置 有 ・ 無）
A43: 住戸用自動火災報知設備・共同住宅用非常警報設備 | R43: ②
A44: 試 験 項 目 | L44: 種別・容量等の内容 | Q44: 結果
A45: 外観試験 | B45: 住戸用自動火災報知設備 | C45: 警戒区域 | F45: 警戒区域の設定 | L45: ――――――― | Q45: 〇 | AG45: 〇 | AH45: 戸外表示機組込
C46: ＊住戸用受信機 | F46: 設置場所等 | I46: 設置場所 | L46: =住戸部【その2】!Y5 | Q46: 〇 | T46: インターホン | AG46: ／ | AH46: 各住戸パイプシャフト
...

Sheet 自動火災報知設備その１
A1: 別記様式第11 | R1: （その１）①
A3: 自 動 火 災 報 知 設 備 試 験 結 果 報 告 書
A5: 試験実施日 令和 年 月 日
H7: 試験実施者
I9: 住 所 | K9: =表紙!L8
I10: 氏 名 | K10: =表紙!L9
A12: 用途 | C12: （ ５ ）項 ロ・共同住宅
A13: 延べ面積 | C13: =面積概要表!L8 | J13: 階 数 | L13: =面積概要表!AC6
A14: 受信機 | C14: 蓄積式・二信号式・アナログ式・自動試験機能付き・遠隔試験機能付き・無線式・その他（ ）
C15: ="Ｐ・ＧＰ型"&'共用部【その2】 '!Q3&" 級 回線数 "&'共用部【その2】 '!U3 | I15: Ｒ・ＧＲ型自火報点数 点・その他点数 点・予備点数 点
C16: 定格電圧 | E16: ＡＣ 100 Ｖ ・ ＤＣ Ｖ
C17: 予備電源 | E17: NiCd・その他（ ） | K17: =IF('共用部【その2】 '!R5="","予備電源（DC Ｖ AH）","DC "&'共用部【その2】 '!R5&"V " &'共用部【その2】 '!T5&"AH")
A18: 発信機 | F18: 型 | G18: ='共用部【その2】 '!Q3 | H18: 級 | J18: 屋内型 | L18: 個 | N18: 屋外型 | P18: 個
C19: （無線式 型 級 屋内型 個 屋外型 個）
A20: 中 継 器 | B20: アナログ式・蓄積式・自動試験機能付・遠隔試験機能付・・無線式・他（ ） 回線 | L20: 予備電源 有 ( V AH)・無 | P20: 設置台数 台
B21: アナログ式・蓄積式・自動試験機能付・遠隔試験機能付・・無線式・他（ ） 回線 | L21: 予備電源 有 ( V AH)・無 | P21: 設置台数 台
B22: アナログ式・蓄積式・自動試験機能付・遠隔試験機能付・・無線式・他（ ） 回線 | L22: 予備電源 有 ( V AH)・無 | P22: 設置台数 台
B23: アナログ式・蓄積式・自動試験機能付・遠隔試験機能付・・無線式・他（ ） 回線 | L23: 予備電源 有 ( V AH)・無 | P23: 設置台数 台
A24: 感知器 | B24: 機種 | L24: 自 | M24: 遠 | N24: 種別 | Q24: 個数
B25: 【共用部】
B26: =共用部【その1】!B4&" "&共用部【その1】!D4&共用部【その1】!G4 | L26: =IF(共用部【その1】!J4="","",共用部【その1】!J4) | M26: =IF(共用部【その1】!K4="","",共用部【その1】!K4) | N26: =IF(共用部【その1】!L4="","",共用部【その1】!L4) | Q26: =IF(共用部【その1】!M4="","",共用部【その1】!M4)
B27: =共用部【その1】!B6&" "&共用部【その1】!D6&共用部【その1】!G6 | L27: =IF(共用部【その1】!J6="","",共用部【その1】!J6) | M27: =IF(共用部【その1】!K6="","",共用部【その1】!K6) | N27: =IF(共用部【その1】!L6="","",共用部【その1】!L6) | Q27: =IF(共用部【その1】!M6="","",共用部【その1】!M6)
L28: =IF(共用部【その1】!J8="","",共用部【その1】!J8) | M28: =IF(共用部【その1】!K8="","",共用部【その1】!K8) | N28: =IF(共用部【その1】!L8="","",共用部【その1】!L8) | Q28: =IF(共用部【その1】!M8="","",共用部【その1】!M8)
L29: =IF(共用部【その1】!J10="","",共用部【その1】!J10) | M29: =IF(共用部【その1】!K10="","",共用部【その1】!K10) | N29: =IF(共用部【その1】!L10="","",共用部【その1】!L10) | Q29: =IF(共用部【その1】!M10="","",共用部【その1】!M10)
B30: 【専有部】
B31: =住戸部【その1】!B4&" "&住戸部【その1】!D4&住戸部【その1】!G4 | L31: =IF(住戸部【その1】!J4="","",住戸部【その1】!J4) | M31: =IF(住戸部【その1】!K4="","",住戸部【その1】!K4) | N31: =IF(住戸部【その1】!L4="","",住戸部【その1】!L4) | Q31: =IF(住戸部【その1】!M4="","",住戸部【その1】!M4)
B32: =住戸部【その1】!B6&" "&住戸部【その1】!D6&住戸部【その1】!G6 | L32: =IF(住戸部【その1】!J6="","",住戸部【その1】!J6) | M32: =IF(住戸部【その1】!K6="","",住戸部【その1】!K6) | N32: =IF(住戸部【その1】!L6="","",住戸部【その1】!L6) | Q32: =IF(住戸部【その1】!M6="","",住戸部【その1】!M6)
B33: =住戸部【その1】!B8&" "&住戸部【その1】!D8&住戸部【その1】!G8 | L33: =IF(住戸部【その1】!J8="","",住戸部【その1】!J8) | M33: =IF(住戸部【その1】!K8="","",住戸部【その1】!K8) | N33: =IF(住戸部【その1】!L8="","",住戸部【その1】!L8) | Q33: =IF(住戸部【その1】!M8="","",住戸部【その1】!M8)
B34: =住戸部【その1】!B10&" "&住戸部【その1】!D10&住戸部【その1】!G10 | L34: =IF(住戸部【その1】!J10="","",住戸部【その1】!J10) | M34: =IF(住戸部【その1】!K10="","",住戸部【その1】!K10) | N34: =IF(住戸部【その1】!L10="","",住戸部【その1】!L10) | Q34: =IF(住戸部【その1】!M10="","",住戸部【その1】!M10)
A35: 音響装置 | B35: 種別 | I35: 種類 | K35: 電圧 | N35: 電流 | Q35: 個
B36: 主音響装備(内蔵されているものを除く。) | K36: ＤＣ Ｖ | N36: ｍＡ | Q36: 個
B37: 副音響装備(内蔵されているものを除く。) | K37: ＤＣ Ｖ | N37: ｍＡ | Q37: 個
B38: 地区音響装置 | K38: ＤＣ Ｖ | N38: ｍＡ | Q38: 個
K39: ＤＣ Ｖ | N39: ｍＡ | Q39: 個
K40: ＤＣ Ｖ | N40: ｍＡ | Q40: 個
B41: 放送設備との連動 | I41: 有 ・ 無
B42: 鳴動方式 | I42: 一斉鳴動 ・ 区分鳴動
A43: 自動火災報知設備 | R43: ②
A44: 試 験 項 目 | K44: 種別・容量等の内容 | R44: 結果
A45: 外 観 試 験 | B45: 警戒区域 | E45: 警戒区域の設定 | K45: ――――― | R45: ○
...

Sheet 自動火災報知設備その２
A1: 自動火災報知設備 | N1: （その２）
A2: 警 戒 区 域 | C2: 感知器（多信号又はアナログ式以外のもの） | M2: 地区音響装置 | N2: 結果
A3: 受信機の表示番号 | B3: 名称 | C3: 差動式 | F3: 補償式スポット型 | G3: 定温式 | I3: 煙感知器 | L3: 炎感知器
C4: 分布型 | D4: スポット型 | G4: スポット型 | H4: 感知線型 | I4: イオン化式スポット型 | J4: 光電式
J5: スポット型 | K5: 分離型
A6: 1 | B6: 1階 | D6: 2 | J6: 1 | M6: 1 | N6: 〇
A7: 2 | B7: 2階 | D7: 1 | M7: 1 | N7: 〇
A8: 3 | B8: 3階 | D8: 1 | M8: 1 | N8: 〇
A9: 4 | B9: 4階 | D9: 1 | M9: 1 | N9: 〇
A10: 5 | B10: 5階 | D10: 1 | M10: 1 | N10: 〇
A11: 6 | B11: 6階 | D11: 1 | M11: 1 | N11: 〇
A12: 7 | B12: 7階 | D12: 1 | M12: 1 | N12: 〇
A13: 8 | B13: 8階 | D13: 1 | M13: 1 | N13: 〇
A14: 9 | B14: 9階 | D14: 1 | M14: 1 | N14: 〇
A15: 10 | B15: 10階 | D15: 1 | M15: 1 | N15: 〇
A16: 11 | B16: 11階 | D16: 1 | E16: 12 | G16: 9 | M16: 1 | N16: 〇
A17: 12 | B17: 12階 | D17: 1 | E17: 12 | G17: 9 | M17: 1 | N17: 〇
A18: 13 | B18: 13階 | D18: 1 | E18: 12 | G18: 9 | M18: 1 | N18: 〇
A19: 14 | B19: 14階 | D19: 1 | E19: 12 | G19: 9 | M19: 1 | N19: 〇
A20: 15 | B20: 15階 | D20: 1 | E20: 12 | G20: 10 | M20: 1 | N20: 〇
A21: 16 | B21: EV機械室 | J21: 1 | N21: 〇
B23: ※下線太字は宅内設置数
A24: 合 計 | D24: =SUM(D6:D23)+SUM(E6:E23) | G24: =SUM(G6:G23) | J24: =SUM(J6:J23) | M24: =SUM(M6:M23)
D25: =SUM(E6:E23)
A26: 備考１ この用紙の大きさは、日本産業規格Ａ４とすること。
A27: ２ 選択肢のある欄は、該当する事項を○印で囲むこと。
A28: ３ 非常電源（内蔵型以外のもの）及び配線についての試験結果報告書を添付すること。
A29: ４ 蓄積式中継器の機能試験は、感知器の作動試験及び発信機の作動により確認するものとする。
A30: ５ 複合式の感知器の試験は、それぞれの種別に応じて行うものとする。
A31: ６ 総合操作盤が設けられているものにあっては、総合操作盤についての試験結果報告書を添付すること。

Sheet 火報_その1
A1: 共同住宅用自動火災報知設備 | Q1: ④
Q2: 共用部 その1
A3: 警戒区域又は住戸等 | C3: 住戸用受信機 | D3: 感知器 | M3: 音声警報装置 | N3: 戸外表示器 | O3: 結果 | Q3: 備考
A4: 住棟受信機の表示番号 | B4: 名称等 | D4: 差動式スポット型 | E4: 定温式スポット型 | F4: 補償式スポット型 | G4: 熱アナログ式スポット型 | H4: 光電式スポット型 | I4: 光電アナログ式スポット型 | J4: イオン化式スポット型 | K4: イオン化アナログ式スポット型 | L4: 炎感知器 | O4: 外観試験 | P4: 機能試験
A5: 1 | B5: 1階 | D5: 8 | E5: 11 | O5: =IF(COUNTA(C5:N5)=0,"","〇") | P5: =IF(COUNTA(C5:N5)=0,"","〇")
A6: 2 | B6: エレベーター | H6: 1 | O6: =IF(COUNTA(C6:N6)=0,"","〇") | P6: =IF(COUNTA(C6:N6)=0,"","〇")
O7: =IF(COUNTA(C7:N7)=0,"","〇") | P7: =IF(COUNTA(C7:N7)=0,"","〇")
O8: =IF(COUNTA(C8:N8)=0,"","〇") | P8: =IF(COUNTA(C8:N8)=0,"","〇")
O9: =IF(COUNTA(C9:N9)=0,"","〇") | P9: =IF(COUNTA(C9:N9)=0,"","〇")
O10: =IF(COUNTA(C10:N10)=0,"","〇") | P10: =IF(COUNTA(C10:N10)=0,"","〇")
O11: =IF(COUNTA(C11:N11)=0,"","〇") | P11: =IF(COUNTA(C11:N11)=0,"","〇")
O12: =IF(COUNTA(C12:N12)=0,"","〇") | P12: =IF(COUNTA(C12:N12)=0,"","〇")
O13: =IF(COUNTA(C13:N13)=0,"","〇") | P13: =IF(COUNTA(C13:N13)=0,"","〇")
O14: =IF(COUNTA(C14:N14)=0,"","〇") | P14: =IF(COUNTA(C14:N14)=0,"","〇")
O15: =IF(COUNTA(C15:N15)=0,"","〇") | P15: =IF(COUNTA(C15:N15)=0,"","〇")
O16: =IF(COUNTA(C16:N16)=0,"","〇") | P16: =IF(COUNTA(C16:N16)=0,"","〇")
O17: =IF(COUNTA(C17:N17)=0,"","〇") | P17: =IF(COUNTA(C17:N17)=0,"","〇")
O18: =IF(COUNTA(C18:N18)=0,"","〇") | P18: =IF(COUNTA(C18:N18)=0,"","〇")
... O27: =IF(COUNTA(C27:N27)=0,"","〇") | P27: =IF(COUNTA(C27:N27)=0,"","〇")
A28: 小計 | D28: =SUM(D5:D27) | E28: =SUM(E5:E27) | H28: =SUM(H5:H27)
A29: 備考
A34: 備考１ この用紙の大きさは、日本産業規格Ａ４とすること。
A35: ２ 共用部分にあっては住棟受信機の表示番号、警戒区域ごとに、住戸等にあっては住戸等ごとに各欄に掲げ る設備等の個数を記入すること。
A37: ３ 結果の欄には、住棟受信機の表示番号、警戒区域又は住戸等ごとに各欄に掲げる設備等の試験結果が全て 良の場合は○、一部でも否である場合は×を記入すること。

Sheet 火報_その2
A1: 共同住宅用自動火災報知設備 | Q1: ④
Q2: 専有部 その1
A3: 警戒区域又は住戸等 | C3: 住戸用受信機 | D3: 感知器 | M3: 音声警報装置 | N3: 戸外表示器 | O3: 結果 | Q3: 備考
A4: 住棟受信機の表示番号 | B4: 名称等 | D4: 差動式スポット型 | E4: 定温式スポット型 | F4: 補償式スポット型 | G4: 熱アナログ式スポット型 | H4: 光電式スポット型 | I4: 光電アナログ式スポット型 | J4: イオン化式スポット型 | K4: イオン化アナログ式スポット型 | L4: 炎感知器 | O4: 外観試験 | P4: 機能試験
B5: 201 | C5: 1 | D5: 5 | E5: 1 | N5: 1 | O5: =IF(COUNTA(C5:N5)=0,"","〇") | P5: =IF(COUNTA(C5:N5)=0,"","〇")
B6: 202 | C6: 1 | D6: 5 | E6: 1 | N6: 1 | O6: =IF(COUNTA(C6:N6)=0,"","〇") | P6: =IF(COUNTA(C6:N6)=0,"","〇")
B7: 203 | C7: 1 | D7: 5 | E7: 1 | N7: 1 | O7: =IF(COUNTA(C7:N7)=0,"","〇") | P7: =IF(COUNTA(C7:N7)=0,"","〇")
B8: 205 | C8: 1 | D8: 5 | E8: 1 | N8: 1 | O8: =IF(COUNTA(C8:N8)=0,"","〇") | P8: =IF(COUNTA(C8:N8)=0,"","〇")
B9: 301 | C9: 1 | D9: 4 | E9: 1 | N9: 1 | O9: =IF(COUNTA(C9:N9)=0,"","〇") | P9: =IF(COUNTA(C9:N9)=0,"","〇")
B10: 302 | C10: 1 | D10: 5 | E10: 1 | N10: 1 | O10: =IF(COUNTA(C10:N10)=0,"","〇") | P10: =IF(COUNTA(C10:N10)=0,"","〇")
B11: 303 | C11: 1 | D11: 5 | E11: 1 | N11: 1 | O11: =IF(COUNTA(C11:N11)=0,"","〇") | P11: =IF(COUNTA(C11:N11)=0,"","〇")
B12: 305 | C12: 1 | D12: 4 | E12: 1 | N12: 1 | O12: =IF(COUNTA(C12:N12)=0,"","〇") | P12: =IF(COUNTA(C12:N12)=0,"","〇")
B13: 401 | C13: 1 | D13: 4 | E13: 1 | N13: 1 | O13: =IF(COUNTA(C13:N13)=0,"","〇") | P13: =IF(COUNTA(C13:N13)=0,"","〇")
B14: 402 | C14: 1 | D14: 5 | E14: 1 | N14: 1 | O14: =IF(COUNTA(C14:N14)=0,"","〇") | P14: =IF(COUNTA(C14:N14)=0,"","〇")
B15: 403 | C15: 1 | D15: 5 | E15: 1 | N15: 1 | O15: =IF(COUNTA(C15:N15)=0,"","〇") | P15: =IF(COUNTA(C15:N15)=0,"","〇")
B16: 405 | C16: 1 | D16: 5 | E16: 1 | N16: 1 | O16: =IF(COUNTA(C16:N16)=0,"","〇") | P16: =IF(COUNTA(C16:N16)=0,"","〇")
... B20: 505 | C20: 1 | D20: 5 | E20: 1 | N20: 1 | O20: =IF(COUNTA(C20:N20)=0,"","〇") | P20: =IF(COUNTA(C20:N20)=0,"","〇")
B21: 601 | O21: =IF(COUNTA(C21:N21)=0,"","〇") | P21: =IF(COUNTA(C21:N21)=0,"","〇")
B22: 602 | C22: 1 | D22: 5 | E22: 1 | N22: 1 | O22: =IF(COUNTA(C22:N22)=0,"","〇") | P22: =IF(COUNTA(C22:N22)=0,"","〇")
B23: 603 | C23: 1 | D23: 5 | E23: 1 | N23: 1 | O23: =IF(COUNTA(C23:N23)=0,"","〇") | P23: =IF(COUNTA(C23:N23)=0,"","〇")
B24: 605 | C24: 1 | D24: 5 | E24: 1 | N24: 1 | O24: =IF(COUNTA(C24:N24)=0,"","〇") | P24: =IF(COUNTA(C24:N24)=0,"","〇")
O25: =IF(COUNTA(C25:N25)=0,"","〇") | P25: =IF(COUNTA(C25:N25)=0,"","〇")
O26: =IF(COUNTA(C26:N26)=0,"","〇") | P26: =IF(COUNTA(C26:N26)=0,"","〇")
A27: 小計 | C27: =SUM(C5:C26) | D27: =SUM(D5:D26) | E27: =SUM(E5:E26) | N27: =SUM(N5:N26) | O27: =IF(COUNTA(C27:N27)=0,"","〇") | P27: =IF(COUNTA(C27:N27)=0,"","〇")
A28: 備考
A33: 備考１ この用紙の大きさは、日本産業規格Ａ４とすること。
A34: ２ 共用部分にあっては住棟受信機の表示番号、警戒区域ごとに、住戸等にあっては住戸等ごとに各欄に掲げ る設備等の個数を記入すること。
A36: ３ 結果の欄には、住棟受信機の表示番号、警戒区域又は住戸等ごとに各欄に掲げる設備等の試験結果が全て 良の場合は○、一部でも否である場合は×を記入すること。

Sheet 火報_その３
A1: 共同住宅用自動火災報知設備 | Q1: ④
Q2: 専有部 その1
A3: 警戒区域又は住戸等 | C3: 住戸用受信機 | D3: 感知器 | M3: 音声警報装置 | N3: 戸外表示器 | O3: 結果 | Q3: 備考
A4: 住棟受信機の表示番号 | B4: 名称等 | D4: 差動式スポット型 | E4: 定温式スポット型 | F4: 補償式スポット型 | G4: 熱アナログ式スポット型 | H4: 光電式スポット型 | I4: 光電アナログ式スポット型 | J4: イオン化式スポット型 | K4: イオン化アナログ式スポット型 | L4: 炎感知器 | O4: 外観試験 | P4: 機能試験
B5: 701 | C5: 1 | D5: 5 | E5: 1 | N5: 1 | O5: =IF(COUNTA(C5:N5)=0,"","〇") | P5: =IF(COUNTA(C5:N5)=0,"","〇")
B6: 702 | C6: 1 | D6: 5 | E6: 1 | N6: 1 | O6: =IF(COUNTA(C6:N6)=0,"","〇") | P6: =IF(COUNTA(C6:N6)=0,"","〇")
B7: 703 | C7: 1 | D7: 5 | E7: 1 | N7: 1 | O7: =IF(COUNTA(C7:N7)=0,"","〇") | P7: =IF(COUNTA(C7:N7)=0,"","〇")
B8: 705 | C8: 1 | D8: 5 | E8: 1 | N8: 1 | O8: =IF(COUNTA(C8:N8)=0,"","〇") | P8: =IF(COUNTA(C8:N8)=0,"","〇")
B9: 801 | C9: 1 | D9: 4 | E9: 1 | N9: 1 | O9: =IF(COUNTA(C9:N9)=0,"","〇") | P9: =IF(COUNTA(C9:N9)=0,"","〇")
B10: 802 | C10: 1 | D10: 5 | E10: 1 | N10: 1 | O10: =IF(COUNTA(C10:N10)=0,"","〇") | P10: =IF(COUNTA(C10:N10)=0,"","〇")
B11: 803 | C11: 1 | D11: 5 | E11: 1 | N11: 1 | O11: =IF(COUNTA(C11:N11)=0,"","〇") | P11: =IF(COUNTA(C11:N11)=0,"","〇")
B12: 805 | C12: 1 | D12: 4 | E12: 1 | N12: 1 | O12: =IF(COUNTA(C12:N12)=0,"","〇") | P12: =IF(COUNTA(C12:N12)=0,"","〇")
B13: 901 | C13: 1 | D13: 4 | E13: 1 | N13: 1 | O13: =IF(COUNTA(C13:N13)=0,"","〇") | P13: =IF(COUNTA(C13:N13)=0,"","〇")
B14: 902 | C14: 1 | D14: 4 | E14: 1 | N14: 1 | O14: =IF(COUNTA(C14:N14)=0,"","〇") | P14: =IF(COUNTA(C14:N14)=0,"","〇")
B15: 903 | C15: 1 | D15: 4 | E15: 1 | N15: 1 | O15: =IF(COUNTA(C15:N15)=0,"","〇") | P15: =IF(COUNTA(C15:N15)=0,"","〇")
B16: 905 | C16: 1 | D16: 4 | E16: 1 | N16: 1 | O16: =IF(COUNTA(C16:N16)=0,"","〇") | P16: =IF(COUNTA(C16:N16)=0,"","〇")
... B24: 1105 | C24: 1 | D24: 5 | E24: 1 | N24: 1 | O24: =IF(COUNTA(C24:N24)=0,"","〇") | P24: =IF(COUNTA(C24:N24)=0,"","〇")
O25: =IF(COUNTA(C25:N25)=0,"","〇") | P25: =IF(COUNTA(C25:N25)=0,"","〇")
O26: =IF(COUNTA(C26:N26)=0,"","〇") | P26: =IF(COUNTA(C26:N26)=0,"","〇")
O27: =IF(COUNTA(C27:N27)=0,"","〇") | P27: =IF(COUNTA(C27:N27)=0,"","〇")
A28: 小計 | C28: =SUM(C5:C27) | D28: =SUM(D5:D27) | E28: =SUM(E5:E27) | N28: =SUM(N5:N27)
A29: 備考
A34: 備考１ この用紙の大きさは、日本産業規格Ａ４とすること。
A35: ２ 共用部分にあっては住棟受信機の表示番号、警戒区域ごとに、住戸等にあっては住戸等ごとに各欄に掲げ る設備等の個数を記入すること。
A37: ３ 結果の欄には、住棟受信機の表示番号、警戒区域又は住戸等ごとに各欄に掲げる設備等の試験結果が全て 良の場合は○、一部でも否である場合は×を記入すること。

Sheet 火報_その4
A1: 共同住宅用自動火災報知設備 | Q1: ④
Q2: 専有部 その1
A3: 警戒区域又は住戸等 | C3: 住戸用受信機 | D3: 感知器 | M3: 音声警報装置 | N3: 戸外表示器 | O3: 結果 | Q3: 備考
A4: 住棟受信機の表示番号 | B4: 名称等 | D4: 差動式スポット型 | E4: 定温式スポット型 | F4: 補償式スポット型 | G4: 熱アナログ式スポット型 | H4: 光電式スポット型 | I4: 光電アナログ式スポット型 | J4: イオン化式スポット型 | K4: イオン化アナログ式スポット型 | L4: 炎感知器 | O4: 外観試験 | P4: 機能試験
B5: 1201 | C5: 1 | D5: 5 | E5: 1 | N5: 1 | O5: =IF(COUNTA(C5:N5)=0,"","〇") | P5: =IF(COUNTA(C5:N5)=0,"","〇")
B6: 1202 | C6: 1 | D6: 4 | E6: 1 | N6: 1 | O6: =IF(COUNTA(C6:N6)=0,"","〇") | P6: =IF(COUNTA(C6:N6)=0,"","〇")
B7: 1203 | C7: 1 | D7: 4 | E7: 1 | N7: 1 | O7: =IF(COUNTA(C7:N7)=0,"","〇") | P7: =IF(COUNTA(C7:N7)=0,"","〇")
B8: 1205 | C8: 1 | D8: 5 | E8: 1 | N8: 1 | O8: =IF(COUNTA(C8:N8)=0,"","〇") | P8: =IF(COUNTA(C8:N8)=0,"","〇")
B9: 1301 | C9: 1 | D9: 5 | E9: 1 | N9: 1 | O9: =IF(COUNTA(C9:N9)=0,"","〇") | P9: =IF(COUNTA(C9:N9)=0,"","〇")
B10: 1302 | C10: 1 | D10: 4 | E10: 1 | N10: 1 | O10: =IF(COUNTA(C10:N10)=0,"","〇") | P10: =IF(COUNTA(C10:N10)=0,"","〇")
B11: 1303 | C11: 1 | D11: 4 | E11: 1 | N11: 1 | O11: =IF(COUNTA(C11:N11)=0,"","〇") | P11: =IF(COUNTA(C11:N11)=0,"","〇")
B12: 1305 | C12: 1 | D12: 4 | E12: 1 | N12: 1 | O12: =IF(COUNTA(C12:N12)=0,"","〇") | P12: =IF(COUNTA(C12:N12)=0,"","〇")
B13: 1401 | C13: 1 | D13: 7 | E13: 1 | N13: 1 | O13: =IF(COUNTA(C13:N13)=0,"","〇") | P13: =IF(COUNTA(C13:N13)=0,"","〇")
B14: 1402 | O14: =IF(COUNTA(C14:N14)=0,"","〇") | P14: =IF(COUNTA(C14:N14)=0,"","〇") | R14: 6.1
B15: 1403 | C15: 1 | D15: 4 | E15: 1 | N15: 1 | O15: =IF(COUNTA(C15:N15)=0,"","〇") | P15: =IF(COUNTA(C15:N15)=0,"","〇")
O16: =IF(COUNTA(C16:N16)=0,"","〇") | P16: =IF(COUNTA(C16:N16)=0,"","〇")
O17: =IF(COUNTA(C17:N17)=0,"","〇") | P17: =IF(COUNTA(C17:N17)=0,"","〇")
O18: =IF(COUNTA(C18:N18)=0,"","〇") | P18: =IF(COUNTA(C18:N18)=0,"","〇")
O19: =IF(COUNTA(C19:N19)=0,"","〇") | P19: =IF(COUNTA(C19:N19)=0,"","〇")
O20: =IF(COUNTA(C20:N20)=0,"","〇") | P20: =IF(COUNTA(C20:N20)=0,"","〇")
O21: =IF(COUNTA(C21:N21)=0,"","〇") | P21: =IF(COUNTA(C21:N21)=0,"","〇")
O22: =IF(COUNTA(C22:N22)=0,"","〇") | P22: =IF(COUNTA(C22:N22)=0,"","〇")
O23: =IF(COUNTA(C23:N23)=0,"","〇") | P23: =IF(COUNTA(C23:N23)=0,"","〇")
O24: =IF(COUNTA(C24:N24)=0,"","〇") | P24: =IF(COUNTA(C24:N24)=0,"","〇")
O25: =IF(COUNTA(C25:N25)=0,"","〇") | P25: =IF(COUNTA(C25:N25)=0,"","〇")
O26: =IF(COUNTA(C26:N26)=0,"","〇") | P26: =IF(COUNTA(C26:N26)=0,"","〇")
O27: =IF(COUNTA(C27:N27)=0,"","〇") | P27: =IF(COUNTA(C27:N27)=0,"","〇")
A28: 小計 | C28: =SUM(C5:C27) | D28: =SUM(D5:D27) | E28: =SUM(E5:E27) | N28: =SUM(N5:N27)
A29: 合計 | C29: =その2!C27+その３!C28+その4!C28 | D29: =その2!D27+その３!D28+その4!D28 | E29: =その2!E27+その３!E28+その4!E28 | N29: =その2!N27+その３!N28+その4!N28
A30: 備考
A35: 備考１ この用紙の大きさは、日本産業規格Ａ４とすること。
A36: ２ 共用部分にあっては住棟受信機の表示番号、警戒区域ごとに、住戸等にあっては住戸等ごとに各欄に掲げ る設備等の個数を記入すること。
A38: ３ 結果の欄には、住棟受信機の表示番号、警戒区域又は住戸等ごとに各欄に掲げる設備等の試験結果が全て 良の場合は○、一部でも否である場合は×を記入すること。
