Workbook

Sheet 入力フォーム
A1: 消防設備工事 統合入力フォーム
A2: 黄色セル＝入力必要 緑色セル＝自動計算
A4: 【基本情報】
A5: 担当消防署
A6: 届出日（例：2025/4/1）
A7: 届出者名
A8: 工事場所（住所）
A9: 防火対象物の名称
A10: 工事整備対象設備等の種類 | B10: 自動火災報知設備
A11: 用途コード（例：5項ロ）
A12: 用途名称 | B12: 共同住宅
A13: 主要構造部 | B13: 耐火構造
A14: 地上階数
A15: 地下階数
A16: 塔屋階数
A17: 延べ床面積（㎡）
A18: 着工予定日
A19: 完成予定日
A20: 理事長名
A22: 【施工者情報】
A23: 施工会社名 | B23: 株式会社 TSCアクセス・プロ
A24: 代表者名 | B24: 代表取締役 中村 勇
A25: 施工会社住所 | B25: 名古屋市中区栄４丁目１６番３号 山光堂ビル５階
A26: 電話番号 | B26: 052-269-9100
A28: 【消防設備士情報】担当者選択
A29: 氏名 | B29: 住所 | C29: 免状種類 | D29: 交付年月日 | E29: 交付番号 | F29: 講習年月 | G29: 受講地 | H29: 交付知事 | I29: 電工資格
A30: 河合 佑樹 | B30: 愛知県尾張旭市晴丘町東236番地4 | C30: 甲4 | D30: R5年7月21日 | E30: 第00324号 | G30: 愛知 | H30: 愛知 | I30: 第二種電気工事士 R3年9月7日 第144528号
A31: 戸田 健仁 | B31: 愛知県長久手市西原山1-1 ｾﾝﾄｱｰｽ502 | C31: 甲4 | D31: R5年11月7日 | E31: 第00448号 | G31: 愛知 | H31: 愛知 | I31: 第二種電気工事士 H22年10月13日 第106680号
A32: 棚町 征 | B32: 岐阜県土岐市泉町大富195番地の249 | C32: 甲4 | D32: H14年10月30日 | E32: 第00009号 | F32: 令和元年10月 | G32: 愛知 | H32: 愛知 | I32: 第二種電気工事士 H27年12月4日 岐阜県第31879号
A34: 届出者（選択） | B34: 戸田 健仁
A35: 試験実施者（選択）
A36: 配線試験実施者（選択） | B36: 戸田 健仁
A38: 【受信機・機器情報】
A39: 共用部 受信機型級（例：1） | B39: 1
A40: 共用部 回線数（例：10/10） | B40: 10/10
A41: 共用部 予備電源DC（V） | B41: 24
A42: 共用部 予備電源（AH） | B42: 0.45
A43: 共用部 受信機設置場所 | B43: 管理人室
A44: 共用部 受信機メーカー | B44: パナソニック㈱
A45: 共用部 受信機型式番号（受第）
...

Sheet 共用部感知器
A1: 共用部 感知器・設備 入力表
A3: 警戒区域番号 | B3: 名称等 | C3: 住戸用受信機 | D3: 差動式スポット型 | E3: 定温式スポット型 | F3: 補償式スポット型 | G3: 熱アナログ式スポット型 | H3: 光電式スポット型 | I3: 光電アナログ式スポット型 | J3: イオン化式スポット型 | K3: イオン化アナログ式スポット型 | L3: 炎感知器 | M3: 音声警報装置 | N3: 戸外表示器 | O3: 外観試験 | P3: 機能試験 | Q3: 備考
A4: 1 | B4: 1階ｴﾝﾄﾗﾝｽ | E4: 5 | H4: 1 | O4: =IF(COUNTA(C4:N4)=0,"","〇") | P4: =IF(COUNTA(C4:N4)=0,"","〇")
A5: 2 | B5: エレベーター | H5: 1 | O5: =IF(COUNTA(C5:N5)=0,"","〇") | P5: =IF(COUNTA(C5:N5)=0,"","〇")
A6: 3 | B6: 1階共用部 防火戸 | H6: 2 | O6: =IF(COUNTA(C6:N6)=0,"","〇") | P6: =IF(COUNTA(C6:N6)=0,"","〇")
O7: =IF(COUNTA(C7:N7)=0,"","〇") | P7: =IF(COUNTA(C7:N7)=0,"","〇")
O8: =IF(COUNTA(C8:N8)=0,"","〇") | P8: =IF(COUNTA(C8:N8)=0,"","〇")
O9: =IF(COUNTA(C9:N9)=0,"","〇") | P9: =IF(COUNTA(C9:N9)=0,"","〇")
O10: =IF(COUNTA(C10:N10)=0,"","〇") | P10: =IF(COUNTA(C10:N10)=0,"","〇")
O11: =IF(COUNTA(C11:N11)=0,"","〇") | P11: =IF(COUNTA(C11:N11)=0,"","〇")
O12: =IF(COUNTA(C12:N12)=0,"","〇") | P12: =IF(COUNTA(C12:N12)=0,"","〇")
O13: =IF(COUNTA(C13:N13)=0,"","〇") | P13: =IF(COUNTA(C13:N13)=0,"","〇")
O14: =IF(COUNTA(C14:N14)=0,"","〇") | P14: =IF(COUNTA(C14:N14)=0,"","〇")
O15: =IF(COUNTA(C15:N15)=0,"","〇") | P15: =IF(COUNTA(C15:N15)=0,"","〇")
O16: =IF(COUNTA(C16:N16)=0,"","〇") | P16: =IF(COUNTA(C16:N16)=0,"","〇")
O17: =IF(COUNTA(C17:N17)=0,"","〇") | P17: =IF(COUNTA(C17:N17)=0,"","〇")
O18: =IF(COUNTA(C18:N18)=0,"","〇") | P18: =IF(COUNTA(C18:N18)=0,"","〇")
... O27: =IF(COUNTA(C27:N27)=0,"","〇") | P27: =IF(COUNTA(C27:N27)=0,"","〇")
A28: 小計 | C28: =SUM(C4:C27) | D28: =SUM(D4:D27) | E28: =SUM(E4:E27) | F28: =SUM(F4:F27) | G28: =SUM(G4:G27) | H28: =SUM(H4:H27) | I28: =SUM(I4:I27) | J28: =SUM(J4:J27) | ... N28: =SUM(N4:N27)

Sheet 専有部感知器
A1: 専有部（住戸部）感知器・設備 入力表
A2: ※ 住戸数が多い場合は行を追加してください
A3: 警戒区域番号 | B3: 名称等 | C3: 住戸用受信機 | D3: 差動式スポット型 | E3: 定温式スポット型 | F3: 補償式スポット型 | G3: 熱アナログ式スポット型 | H3: 光電式スポット型 | I3: 光電アナログ式スポット型 | J3: イオン化式スポット型 | K3: イオン化アナログ式スポット型 | L3: 炎感知器 | M3: 音声警報装置 | N3: 戸外表示器 | O3: 外観試験 | P3: 機能試験 | Q3: 備考
O4: =IF(COUNTA(C4:N4)=0,"","〇") | P4: =IF(COUNTA(C4:N4)=0,"","〇")
O5: =IF(COUNTA(C5:N5)=0,"","〇") | P5: =IF(COUNTA(C5:N5)=0,"","〇")
O6: =IF(COUNTA(C6:N6)=0,"","〇") | P6: =IF(COUNTA(C6:N6)=0,"","〇")
O7: =IF(COUNTA(C7:N7)=0,"","〇") | P7: =IF(COUNTA(C7:N7)=0,"","〇")
O8: =IF(COUNTA(C8:N8)=0,"","〇") | P8: =IF(COUNTA(C8:N8)=0,"","〇")
O9: =IF(COUNTA(C9:N9)=0,"","〇") | P9: =IF(COUNTA(C9:N9)=0,"","〇")
O10: =IF(COUNTA(C10:N10)=0,"","〇") | P10: =IF(COUNTA(C10:N10)=0,"","〇")
O11: =IF(COUNTA(C11:N11)=0,"","〇") | P11: =IF(COUNTA(C11:N11)=0,"","〇")
O12: =IF(COUNTA(C12:N12)=0,"","〇") | P12: =IF(COUNTA(C12:N12)=0,"","〇")
O13: =IF(COUNTA(C13:N13)=0,"","〇") | P13: =IF(COUNTA(C13:N13)=0,"","〇")
O14: =IF(COUNTA(C14:N14)=0,"","〇") | P14: =IF(COUNTA(C14:N14)=0,"","〇")
O15: =IF(COUNTA(C15:N15)=0,"","〇") | P15: =IF(COUNTA(C15:N15)=0,"","〇")
... O83: =IF(COUNTA(C83:N83)=0,"","〇") | P83: =IF(COUNTA(C83:N83)=0,"","〇")
A84: 合計 | C84: =SUM(C4:C83) | D84: =SUM(D4:D83) | E84: =SUM(E4:E83) | F84: =SUM(F4:F83) | G84: =SUM(G4:G83) | H84: =SUM(H4:H83) | I84: =SUM(I4:I83) | J84: =SUM(J4:J83) | ... N84: =SUM(N4:N83)

Sheet 共用部概要表入力
A1: 共用部 感知器概要表（プルダウン入力）
A3: 機種名 | B3: 型（スポット型等） | C3: 蓄積 | D3: 自動 | E3: 遠隔 | F3: 種別 | G3: 個数 | H3: 型式番号From | I3: 型式番号To | J3: 製造会社名
A16: 住戸部 感知器概要表（プルダウン入力）
A18: 機種名 | B18: 型（スポット型等） | C18: 蓄積 | D18: 自動 | E18: 遠隔 | F18: 種別 | G18: 個数 | H18: 型式番号From | I18: 型式番号To | J18: 製造会社名

Sheet 警戒区域入力
A1: 自動火災報知設備 警戒区域別 感知器・音響装置（その2）
A3: 表示番号 | B3: 名称 | C3: 差動式分布型 | D3: 差動式スポット型 | E3: 補償式スポット型 | F3: 定温式スポット型 | G3: 定温式感知線型 | H3: イオン化式スポット型 | I3: 光電式スポット型 | J3: 光電式分離型 | K3: 炎感知器 | L3: 地区音響装置 | M3: 結果
A24: 合計 | C24: =SUM(C4:C23) | D24: =SUM(D4:D23) | E24: =SUM(E4:E23) | F24: =SUM(F4:F23) | G24: =SUM(G4:G23) | H24: =SUM(H4:H23) | I24: =SUM(I4:I23) | J24: =SUM(J4:J23) | ... L24: =SUM(L4:L23)

Sheet 面積概要表入力
A1: 面積概要表 入力
A3: 階 | B3: 床面積（㎡） | C3: 用途・室名 | D3: 構造 | E3: 内装天井 | F3: 内装壁
A4: =IF(1<=入力フォーム!B14,"1階","")
A5: =IF(2<=入力フォーム!B14,"2階","")
A6: =IF(3<=入力フォーム!B14,"3階","")
A7: =IF(4<=入力フォーム!B14,"4階","")
A8: =IF(5<=入力フォーム!B14,"5階","")
A9: =IF(6<=入力フォーム!B14,"6階","")
A10: =IF(7<=入力フォーム!B14,"7階","")
A11: =IF(8<=入力フォーム!B14,"8階","")
A12: =IF(9<=入力フォーム!B14,"9階","")
A13: =IF(10<=入力フォーム!B14,"10階","")
A14: =IF(11<=入力フォーム!B14,"11階","")
A15: =IF(12<=入力フォーム!B14,"12階","")
A16: =IF(13<=入力フォーム!B14,"13階","")
A17: =IF(14<=入力フォーム!B14,"14階","")
A18: =IF(15<=入力フォーム!B14,"15階","")

Sheet 提出前チェックリスト
A1: 提出前チェックリスト
A3: No. | B3: チェック項目 | C3: 確認 | D3: 備考
A4: 【着工届】
A5: 1 | B5: 表紙：届出日が記入されているか
A6: 2 | B6: 表紙：届出者名・住所が正しいか
A7: 3 | B7: 表紙：消防設備士の免状情報が正しいか
A8: 4 | B8: 表紙：工事種別に○がついているか
A9: 5 | B9: 表紙：着工予定日・完成予定日が記入されているか
A10: 6 | B10: 面積概要表：延べ床面積が正しいか
A11: 7 | B11: 面積概要表：階数が正しいか
A12: 8 | B12: 共用部概要表：感知器の種類・個数が図面と一致するか
A13: 9 | B13: 共用部概要表：発信機・表示灯の個数が正しいか
A14: 10 | B14: 住戸部概要表：感知器の種類・個数が図面と一致するか
A15: 11 | B15: 住戸部概要表：住戸用受信機台数が正しいか
A16: 12 | B16: 共用部・住戸部の地区音響装置情報が正しいか
... A18: 14 | B18: 図面のコピーに正は色付けされているか
A20: 【設置届】
A21: 1 | B21: 設置届出書：完成年月日が記入されているか
A22: 2 | B22: 試験結果報告書：試験実施日が記入されているか
A23: 3 | B23: 試験結果報告書：試験実施者名・住所が正しいか
A24: 4 | B24: 機器台数一覧：共用部の感知器台数が正しいか
A25: 5 | B25: 機器台数一覧：専有部の感知器台数が正しいか
A26: 6 | B26: 機器台数一覧：結果欄がすべて記入されているか
A27: 7 | B27: 配線試験：絶縁抵抗値が記入されているか
A28: 8 | B28: 配線試験：試験実施者の資格情報が正しいか

Sheet 必要書類一覧
A1: 必要書類一覧
A3: No. | B3: 着工届 | C3: 正・副・控 | D3: No. | E3: 設置届
A4: ① | B4: 表紙（着工届出書） | C4: 正・副・控 | D4: ① | E4: 設置届出書
A5: ② | B5: 面積概要表 | C5: 正・副・控 | D5: ② | E5: 試験結果報告書
A6: ③ | B6: 地図（該当建物に色付け） | C6: 正・副・控 | D6: ② | E6: ・自動火災報知設備試験結果報告書
A7: ④ | B7: 共用部その1・その2 | C7: 正・副・控 | D7: ② | E7: ・共同住宅用自火報試験結果報告書
A8: ⑤ | B8: 住戸部その1・その2 | C8: 正・副・控 | D8: ② | E8: ・住戸用自火報試験結果報告書
A9: ⑥ | B9: 消防に関する機器の図面 | C9: 正・副・控 | D9: ③ | E9: 機器台数一覧
A10: ⑦ | B10: 図面のコピー（正は色付け） | C10: 正・副・控 | D10: ③ | E10: ・共同住宅用非常警報設備
A11: ⑧ | B11: 自火報・インターホンの系統図 | C11: 正・副・控 | D11: ③ | E11: ・住戸用自火報・非常警報設備
A12: ⑨ | B12: 平面図（各フロア図） | C12: 正・副・控 | D12: ④ | E12: 配線試験結果
